Workbook

Sheet Prosjektoversikt
B2: Prosjektoversikt
B3: Implementeringsprosjekt P360
B6: Prosjektnavn | C6: KUNDENAVN Implementering P360 | F6: Prosjektets identifiserte risiko | Q6: Påvirkning
B7: Kunde | C7: KUNDENAVN | F7: ID | G7: Risikobeskrivelse | H7: Konsekvens | I7: Tiltak | J7: Ansvarlig | K7: Kategori | L7: Sannsynlighet | M7: Påvirkning | N7: Risikonivå | P7: Kategorier | Q7: Ubetydelig | R7: Mindre alvorlig | S7: Alvorlig | T7: Kritisk | U7: Katastrofe
B8: Antatt varighet (mnd) | C8: 1 | F8: =ROW() - ROW($F$9) + 1 -> 0 | G8: Det er for høye forventninger knyttet til konfigurasjonsmuligheter | H8: Økt frustrasjon og uenighet mellom partene, økte kostnader og potensielt forsinkelse i prosjektet | I8: Konfigurasjonspakker er lagt inn som opsjon | J8: Rådgiver | K8: Leveranse | L8: Meget sannsynlig | M8: Kritisk | N8: =IFERROR(INDEX($Q$8:$U$12,MATCH(L8,$P$8:$P$12,0),MATCH(M8,$Q$7:$U$7,0)),"") -> Høy | O8: Sannsynlighet | P8: Svært sannsynlig | Q8: Medium | R8: Medium | S8: Høy | T8: Høy | U8: Høy
F9: =ROW() - ROW($F$9) + 1 -> 1 | N9: =IFERROR(INDEX($Q$8:$U$12,MATCH(L9,$P$8:$P$12,0),MATCH(M9,$Q$7:$U$7,0)),"") | P9: Meget sannsynlig | Q9: Lav | R9: Medium | S9: Medium | T9: Høy | U9: Høy
B10: Tidsbudsjett (Overordnet) | F10: =ROW() - ROW($F$9) + 1 -> 2 | N10: =IFERROR(INDEX($Q$8:$U$12,MATCH(L10,$P$8:$P$12,0),MATCH(M10,$Q$7:$U$7,0)),"") | P10: Sannsynlig | Q10: Lav | R10: Medium | S10: Medium | T10: Medium | U10: Høy
B11: Kategori | C11: Timer | D11: Kommentar | F11: =ROW() - ROW($F$9) + 1 -> 3 | N11: =IFERROR(INDEX($Q$8:$U$12,MATCH(L11,$P$8:$P$12,0),MATCH(M11,$Q$7:$U$7,0)),"") | P11: Lite sannsynlig | Q11: Lav | R11: Lav | S11: Medium | T11: Medium | U11: Medium
B12: Konsulenttid | C12: =SUM(C24:C33) -> 378 | F12: =ROW() - ROW($F$9) + 1 -> 4 | N12: =IFERROR(INDEX($Q$8:$U$12,MATCH(L12,$P$8:$P$12,0),MATCH(M12,$Q$7:$U$7,0)),"") | P12: Svært lite sannsynlig | Q12: Lav | R12: Lav | S12: Lav | T12: Lav | U12: Medium
B13: Prosjektledelse | C13: 70 | D13: 0.2 | F13: =ROW() - ROW($F$9) + 1 -> 5 | N13: =IFERROR(INDEX($Q$8:$U$12,MATCH(L13,$P$8:$P$12,0),MATCH(M13,$Q$7:$U$7,0)),"")
B14: Migrering | C14: =C28 -> 0 | F14: =ROW() - ROW($F$9) + 1 -> 6 | N14: =IFERROR(INDEX($Q$8:$U$12,MATCH(L14,$P$8:$P$12,0),MATCH(M14,$Q$7:$U$7,0)),"") | Q14: Påvirkning
B15: Statusmøter (internt) | C15: 3 | D15: Kan justeres | F15: =ROW() - ROW($F$9) + 1 -> 7 | N15: =IFERROR(INDEX($Q$8:$U$12,MATCH(L15,$P$8:$P$12,0),MATCH(M15,$Q$7:$U$7,0)),"") | P15: Antall | Q15: Ubetydelig | R15: Mindre alvorlig | S15: Alvorlig | T15: Kritisk | U15: Katastrofe
B16: Statusmøter (eksternt) | D16: Kan justeres | F16: =ROW() - ROW($F$9) + 1 -> 8 | N16: =IFERROR(INDEX($Q$8:$U$12,MATCH(L16,$P$8:$P$12,0),MATCH(M16,$Q$7:$U$7,0)),"") | O16: Sannsynlighet | P16: Svært sannsynlig | Q16: =IF(COUNTIFS($L$8:$L$31,$P8,$M$8:$M$31,$Q$7)=0,"",COUNTIFS($L$8:$L$31,$P8,$M$8:$M$31,$Q$7)) | R16: =IF(COUNTIFS($L$8:$L$31,$P8,$M$8:$M$31,$R$7)=0,"",COUNTIFS($L$8:$L$31,$P8,$M$8:$M$31,$R$7)) | S16: =IF(COUNTIFS($L$8:$L$31,P8,$M$8:$M$31,$S$7)=0,"",COUNTIFS($L$8:$L$31,P8,$M$8:$M$31,$S$7)) | T16: =IF(COUNTIFS($L$8:$L$31,P8,$M$8:$M$31,$T$7)=0,"",COUNTIFS($L$8:$L$31,P8,$M$8:$M$31,$T$7)) | U16: =IF(COUNTIFS($L$8:$L$31,P8,$M$8:$M$31,$U$7)=0,"",COUNTIFS($L$8:$L$31,P8,$M$8:$M$31,$U$7))
B17: Budsjett u/risikopåslag | C17: =SUM(C12:C16) -> 451 | F17: =ROW() - ROW($F$9) + 1 -> 9 | N17: =IFERROR(INDEX($Q$8:$U$12,MATCH(L17,$P$8:$P$12,0),MATCH(M17,$Q$7:$U$7,0)),"") | P17: Meget sannsynlig | Q17: =IF(COUNTIFS($L$8:$L$31,$P9,$M$8:$M$31,$Q$7)=0,"",COUNTIFS($L$8:$L$31,$P9,$M$8:$M$31,$Q$7)) | R17: =IF(COUNTIFS($L$8:$L$31,$P9,$M$8:$M$31,$R$7)=0,"",COUNTIFS($L$8:$L$31,$P9,$M$8:$M$31,$R$7)) | S17: =IF(COUNTIFS($L$8:$L$31,P9,$M$8:$M$31,$S$7)=0,"",COUNTIFS($L$8:$L$31,P9,$M$8:$M$31,$S$7)) | T17: =IF(COUNTIFS($L$8:$L$31,P9,$M$8:$M$31,$T$7)=0,"",COUNTIFS($L$8:$L$31,P9,$M$8:$M$31,$T$7)) -> 1 | U17: =IF(COUNTIFS($L$8:$L$31,P9,$M$8:$M$31,$U$7)=0,"",COUNTIFS($L$8:$L$31,P9,$M$8:$M$31,$U$7))
B18: Risikopåslag | C18: 0.1 | F18: =ROW() - ROW($F$9) + 1 -> 10 | N18: =IFERROR(INDEX($Q$8:$U$12,MATCH(L18,$P$8:$P$12,0),MATCH(M18,$Q$7:$U$7,0)),"") | P18: Sannsynlig | Q18: =IF(COUNTIFS($L$8:$L$31,$P10,$M$8:$M$31,$Q$7)=0,"",COUNTIFS($L$8:$L$31,$P10,$M$8:$M$31,$Q$7)) | R18: =IF(COUNTIFS($L$8:$L$31,$P10,$M$8:$M$31,$R$7)=0,"",COUNTIFS($L$8:$L$31,$P10,$M$8:$M$31,$R$7)) | S18: =IF(COUNTIFS($L$8:$L$31,P10,$M$8:$M$31,$S$7)=0,"",COUNTIFS($L$8:$L$31,P10,$M$8:$M$31,$S$7)) | T18: =IF(COUNTIFS($L$8:$L$31,P10,$M$8:$M$31,$T$7)=0,"",COUNTIFS($L$8:$L$31,P10,$M$8:$M$31,$T$7)) | U18: =IF(COUNTIFS($L$8:$L$31,P10,$M$8:$M$31,$U$7)=0,"",COUNTIFS($L$8:$L$31,P10,$M$8:$M$31,$U$7))
B19: Budsjett m/risikopåslag | C19: =(C12+C13+C14)*(1+C18) -> 492.8 | D19: Påslag kun på konsulenttid, PL og migrering | F19: =ROW() - ROW($F$9) + 1 -> 11 | N19: =IFERROR(INDEX($Q$8:$U$12,MATCH(L19,$P$8:$P$12,0),MATCH(M19,$Q$7:$U$7,0)),"") | P19: Lite sannsynlig | Q19: =IF(COUNTIFS($L$8:$L$31,$P11,$M$8:$M$31,$Q$7)=0,"",COUNTIFS($L$8:$L$31,$P11,$M$8:$M$31,$Q$7)) | R19: =IF(COUNTIFS($L$8:$L$31,$P11,$M$8:$M$31,$R$7)=0,"",COUNTIFS($L$8:$L$31,$P11,$M$8:$M$31,$R$7)) | S19: =IF(COUNTIFS($L$8:$L$31,P11,$M$8:$M$31,$S$7)=0,"",COUNTIFS($L$8:$L$31,P11,$M$8:$M$31,$S$7)) | T19: =IF(COUNTIFS($L$8:$L$31,P11,$M$8:$M$31,$T$7)=0,"",COUNTIFS($L$8:$L$31,P11,$M$8:$M$31,$T$7)) | U19: =IF(COUNTIFS($L$8:$L$31,P11,$M$8:$M$31,$U$7)=0,"",COUNTIFS($L$8:$L$31,P11,$M$8:$M$31,$U$7))
F20: =ROW() - ROW($F$9) + 1 -> 12 | N20: =IFERROR(INDEX($Q$8:$U$12,MATCH(L20,$P$8:$P$12,0),MATCH(M20,$Q$7:$U$7,0)),"") | P20: Svært lite sannsynlig | Q20: =IF(COUNTIFS($L$8:$L$31,$P12,$M$8:$M$31,$Q$7)=0,"",COUNTIFS($L$8:$L$31,$P12,$M$8:$M$31,$Q$7)) | R20: =IF(COUNTIFS($L$8:$L$31,P12,$M$8:$M$31,$R$7)=0,"",COUNTIFS($L$8:$L$31,P12,$M$8:$M$31,$R$7)) | S20: =IF(COUNTIFS($L$8:$L$31,P12,$M$8:$M$31,$S$7)=0,"",COUNTIFS($L$8:$L$31,P12,$M$8:$M$31,$S$7)) | T20: =IF(COUNTIFS($L$8:$L$31,P12,$M$8:$M$31,$T$7)=0,"",COUNTIFS($L$8:$L$31,P12,$M$8:$M$31,$T$7)) | U20: =IF(COUNTIFS($L$8:$L$31,P12,$M$8:$M$31,$U$7)=0,"",COUNTIFS($L$8:$L$31,P12,$M$8:$M$31,$U$7))
B21: Tidsbudsjett (Etter kategori) | F21: =ROW() - ROW($F$9) + 1 -> 13 | N21: =IFERROR(INDEX($Q$8:$U$12,MATCH(L21,$P$8:$P$12,0),MATCH(M21,$Q$7:$U$7,0)),"")
B22: Kategori | C22: Timer | D22: Kommentar | F22: =ROW() - ROW($F$9) + 1 -> 14 | N22: =IFERROR(INDEX($Q$8:$U$12,MATCH(L22,$P$8:$P$12,0),MATCH(M22,$Q$7:$U$7,0)),"")
B23: {='Datavalidering (skjules)'!B14:B24} -> Prosjektledelse | C23: 70 | D23: Kan justeres. Obs! PL-tiden er ikke satt, så sett individuell tid på dette enn så lenge. Se tabellen over | F23: =ROW() - ROW($F$9) + 1 -> 15 | N23: =IFERROR(INDEX($Q$8:$U$12,MATCH(L23,$P$8:$P$12,0),MATCH(M23,$Q$7:$U$7,0)),"")
B24: Analysering | C24: =SUMIF(Fremdriftsplan!$H$1:$H$1542,B24,Fremdriftsplan!$F$1:$F$1542) -> 3.5 | F24: =ROW() - ROW($F$9) + 1 -> 16 | N24: =IFERROR(INDEX($Q$8:$U$12,MATCH(L24,$P$8:$P$12,0),MATCH(M24,$Q$7:$U$7,0)),"")
B25: Dokumentering og spesifisering | C25: =SUMIF(Fremdriftsplan!$H$1:$H$1542,B25,Fremdriftsplan!$F$1:$F$1542) -> 13 | F25: =ROW() - ROW($F$9) + 1 -> 17 | N25: =IFERROR(INDEX($Q$8:$U$12,MATCH(L25,$P$8:$P$12,0),MATCH(M25,$Q$7:$U$7,0)),"")
B26: Utvikling | C26: =SUMIF(Fremdriftsplan!$H$1:$H$1542,B26,Fremdriftsplan!$F$1:$F$1542) -> 0 | F26: =ROW() - ROW($F$9) + 1 -> 18 | N26: =IFERROR(INDEX($Q$8:$U$12,MATCH(L26,$P$8:$P$12,0),MATCH(M26,$Q$7:$U$7,0)),"")
B27: Implementering | C27: =SUMIF(Fremdriftsplan!$H$1:$H$1542,B27,Fremdriftsplan!$F$1:$F$1542) -> 20.5 | F27: =ROW() - ROW($F$9) + 1 -> 19 | N27: =IFERROR(INDEX($Q$8:$U$12,MATCH(L27,$P$8:$P$12,0),MATCH(M27,$Q$7:$U$7,0)),"")
B28: Migrering | C28: =SUMIF(Fremdriftsplan!$H$1:$H$1542,B28,Fremdriftsplan!$F$1:$F$1542) -> 0 | F28: =ROW() - ROW($F$9) + 1 -> 20 | N28: =IFERROR(INDEX($Q$8:$U$12,MATCH(L28,$P$8:$P$12,0),MATCH(M28,$Q$7:$U$7,0)),"")
B29: Installering | C29: =SUMIF(Fremdriftsplan!$H$1:$H$1542,Prosjektoversikt!B29,Fremdriftsplan!$F$1:$F$1542) -> 227 | F29: =ROW() - ROW($F$9) + 1 -> 21 | N29: =IFERROR(INDEX($Q$8:$U$12,MATCH(L29,$P$8:$P$12,0),MATCH(M29,$Q$7:$U$7,0)),"")
B30: Testing | C30: =SUMIF(Fremdriftsplan!$H$1:$H$1542,B30,Fremdriftsplan!$F$1:$F$1542) -> 30.5 | F30: =ROW() - ROW($F$9) + 1 -> 22 | N30: =IFERROR(INDEX($Q$8:$U$12,MATCH(L30,$P$8:$P$12,0),MATCH(M30,$Q$7:$U$7,0)),"")
B31: Rådgivning | C31: =SUMIF(Fremdriftsplan!$H$1:$H$1542,B31,Fremdriftsplan!$F$1:$F$1542) -> 0 | F31: =ROW() - ROW($F$9) + 1 -> 23 | N31: =IFERROR(INDEX($Q$8:$U$12,MATCH(L31,$P$8:$P$12,0),MATCH(M31,$Q$7:$U$7,0)),"")
B32: Opplæring | C32: =SUMIF(Fremdriftsplan!$H$1:$H$1542,B32,Fremdriftsplan!$F$1:$F$1542) -> 42 | F32: =ROW() - ROW($F$9) + 1 -> 24
B33: Generelle møter | C33: =SUMIF(Fremdriftsplan!$H$1:$H$1542,B33,Fremdriftsplan!$F$1:$F$1542) -> 41.5 | D33: Statusmøter er ekstra
B34: Budsjett u/risikopåslag | C34: =SUM(C24:C27,C29:C33) -> 378

Sheet Fremdriftsplan
A1: Fremdriftsplan Implementeringsprosjekt Public 360⁰
B2: Aktiviteter | C2: Min (timer) | D2: Max (timer) | E2: Antall miljøer | F2: Budsjett (timer) | G2: Risikonivå | H2: Kategori | I2: Ansvar (RACI) | J2: Ansvarlig person | K2: Andre deltakere | L2: Start | M2: Slutt | N2: Varighet | O2: Tidspunkt | P2: Fullført | Q2: Aktivitetsbeskrivelse
A3: MP0 | B3: =_xlfn.XLOOKUP(A3,Milepæler!$B$5:$B$13,Milepæler!$C$5:$C$13,) -> Kontrakten er signert | L3: Uke 47
A4: FASE 1 | B4: FORBEREDELSE OG ORGANISERING
A5: MP1 | B5: =_xlfn.XLOOKUP(A5,Milepæler!$B$5:$B$30,Milepæler!$C$5:$C$30,) -> Prosjektet er igangsatt
B6: Forberedelser og organisering av leveranse og ressurser | C6: 10 | D6: 10 | E6: 1 | F6: =IFERROR(AVERAGE(C6:D6)*_xlfn.XLOOKUP(E6,'Datavalidering (skjules)'!$I$7:$I$12,'Datavalidering (skjules)'!$J$7:$J$12),"") -> 10 | G6: Lav | H6: Prosjektledelse | I6: Leverandør (R), Kunde (R) | K6: Kundens prosjektgruppe | L6: Uke 47 | P6: 0 | Q6: Booking av ressurser, interne forberedelser
B7: Kunde innhenter teknisk informasjon (Velkomstbrev) | E7: 1 | F7: =IFERROR(AVERAGE(C7:D7)*_xlfn.XLOOKUP(E7,'Datavalidering (skjules)'!$I$7:$I$12,'Datavalidering (skjules)'!$J$7:$J$12),"") | G7: Lav | H7: Prosjektledelse | I7: Kunde (R) | K7: Kundens prosjektgruppe | L7: man 23.11.26 | M7: tir 24.11.26 | P7: 0 | Q7: Kunde får tilsendt velkomstbrev på forhånd og innhenter teknisk data
B8: Møte: Leverandørens interne oppstartsmøte | C8: 1 | D8: 6 | E8: 1 | F8: =IFERROR(AVERAGE(C8:D8)*_xlfn.XLOOKUP(E8,'Datavalidering (skjules)'!$I$7:$I$12,'Datavalidering (skjules)'!$J$7:$J$12),"") -> 3.5 | G8: Lav | H8: Generelle møter | I8: Leverandør (R) | L8: man 23.11.26 | M8: man 23.11.26 | N8: 1 time | P8: 0 | Q8: Internt oppstartsmøte for Leverandørens prosjektgruppe
B9: Møte: Felles oppstartsmøte med begge prosjektgruppene (Kick-off) | C9: 2 | D9: 6 | E9: 1 | F9: =IFERROR(AVERAGE(C9:D9)*_xlfn.XLOOKUP(E9,'Datavalidering (skjules)'!$I$7:$I$12,'Datavalidering (skjules)'!$J$7:$J$12),"") -> 4 | G9: Lav | H9: Generelle møter | I9: Leverandør (R), Kunde (I) | K9: Kundens prosjektgruppe | L9: tir 24.11.26 | M9: tir 24.11.26 | N9: 2 timer | P9: 0 | Q9: Felles oppstartsmøte for begge prosjektgruppene (Kunden og Leverandøren)
B10: Møte: Teknisk møte | C10: 1 | D10: 2 | E10: 1 | F10: =IFERROR(AVERAGE(C10:D10)*_xlfn.XLOOKUP(E10,'Datavalidering (skjules)'!$I$7:$I$12,'Datavalidering (skjules)'!$J$7:$J$12),"") -> 1.5 | G10: Medium | H10: Generelle møter | I10: Leverandør (R) | K10: Kundens IT | L10: tir 24.11.26 | M10: tir 24.11.26 | N10: 1 time | P10: 0 | Q10: Gjennomgang av tekniske krav (miljø og moduler) og velkomstbrev
B11: Fremdriftsplan oppdateres til v.1.0 | C11: 1 | D11: 1 | E11: 1 | F11: =IFERROR(AVERAGE(C11:D11)*_xlfn.XLOOKUP(E11,'Datavalidering (skjules)'!$I$7:$I$12,'Datavalidering (skjules)'!$J$7:$J$12),"") -> 1 | G11: Lav | H11: Prosjektledelse | I11: Leverandør (R), Kunde (C) | K11: Kundens prosjektleder | L11: tir 24.11.26 | M11: tir 24.11.26 | P11: 0 | Q11: Omforent fremdriftsplan oppdateres
A12: MP2 | B12: =_xlfn.XLOOKUP(A12,Milepæler!$B$5:$B$30,Milepæler!$C$5:$C$30,) -> Omforent fremdriftsplan er godkjent | L12: tir 24.11.26 | M12: tir 24.11.26
A14: FASE 2 | B14: INSTALLERING, OPPLÆRING OG SPESIFISERING
B15: Etablering av miljø m/moduler + verifisering av miljøpålogging | C15: 2 | D15: 3 | E15: 1 | F15: =IFERROR(AVERAGE(C15:D15)*_xlfn.XLOOKUP(E15,'Datavalidering (skjules)'!$I$7:$I$12,'Datavalidering (skjules)'!$J$7:$J$12),"") -> 2.5 | G15: Lav | H15: Prosjektledelse | I15: Leverandør (R) | K15: Kundens prosjektgruppe | L15: ons 25.11.26 | M15: ons 25.11.26 | N15: 1 dag | P15: 0 | Q15: Leverandøren oppretter miljø(er) iht. Avtalen og verifiserer innlogging
B16: Forbered tilkobling til AD Sync | E16: 1 | F16: =IFERROR(AVERAGE(C16:D16)*_xlfn.XLOOKUP(E16,'Datavalidering (skjules)'!$I$7:$I$12,'Datavalidering (skjules)'!$J$7:$J$12),"") | G16: Medium | H16: Installering | I16: Leverandør (R), Kunde (C) | K16: Kundens IT | L16: ons 25.11.26 | M16: ons 25.11.26 | P16: 0 | Q16: Arbeid med tilkobling av AD Sync påbegynnes
A17: MP3 | B17: =_xlfn.XLOOKUP(A17,Milepæler!$B$5:$B$30,Milepæler!$C$5:$C$30,) -> Avtalt miljø er klart for funksjonelt oppsett og verifisering
B18: Innledende møter
B19: Tema: Bli kjent med Kundens rutiner, prosesser og behov | C19: 2 | D19: 5 | E19: 1 | F19: =IFERROR(AVERAGE(C19:D19)*_xlfn.XLOOKUP(E19,'Datavalidering (skjules)'!$I$7:$I$12,'Datavalidering (skjules)'!$J$7:$J$12),"") -> 3.5 | G19: Lav | H19: Analysering | I19: Leverandør (R), Kunde (C) | K19: Kundens prosjektgruppe | L19: ons 25.11.26 | M19: ons 25.11.26 | N19: 2 timer | P19: 0 | Q19: Leverandøren blir kjent med Kundens arbeidsmetoder og prosesser, for å kunne tilpasse anbefalinger og tilbakemeldinger
B20: Opplæring av prosjektgruppe
B21: Leverandøren forbereder miljø til digital kursgjennomføring i Leverandørens kursmiljø | C21: - | D21: 2 | E21: 1 | F21: =IFERROR(AVERAGE(C21:D21)*_xlfn.XLOOKUP(E21,'Datavalidering (skjules)'!$I$7:$I$12,'Datavalidering (skjules)'!$J$7:$J$12),"") -> 2 | G21: Lav | H21: Opplæring | I21: Leverandør (R) | K21: Kundens prosjektgruppe | L21: ons 25.11.26 | M21: ons 25.11.26 | P21: 0 | Q21: Leverandøren forbereder til kursgjennomføring
B22: Kurs: Administratorkurs (3 timer) | C22: - | D22: 6 | E22: 1 | F22: =IFERROR(AVERAGE(C22:D22)*_xlfn.XLOOKUP(E22,'Datavalidering (skjules)'!$I$7:$I$12,'Datavalidering (skjules)'!$J$7:$J$12),"") -> 6 | G22: Lav | H22: Opplæring | I22: Leverandør (R), Kunde (C) | K22: Kundens prosjektgruppe | L22: tor 26.11.26 | M22: tor 26.11.26 | N22: 3 timer | P22: 0 | Q22: Gjennomgang av faglig kursinnhold og -oppgaver
B23: Kurs: Videregåendekurs (3 timer) | C23: - | D23: 6 | E23: 1 | F23: =IFERROR(AVERAGE(C23:D23)*_xlfn.XLOOKUP(E23,'Datavalidering (skjules)'!$I$7:$I$12,'Datavalidering (skjules)'!$J$7:$J$12),"") -> 6 | G23: Lav | H23: Opplæring | I23: Leverandør (R), Kunde (C) | K23: Kundens prosjektgruppe | L23: tor 26.11.26 | M23: tor 26.11.26 | N23: 3 timer | P23: 0 | Q23: Gjennomgang av faglig kursinnhold og -oppgaver
B24: Kurs: Arkivarkurs (3 timer) | C24: - | D24: 6 | E24: 1 | F24: =IFERROR(AVERAGE(C24:D24)*_xlfn.XLOOKUP(E24,'Datavalidering (skjules)'!$I$7:$I$12,'Datavalidering (skjules)'!$J$7:$J$12),"") -> 6 | G24: Lav | H24: Opplæring | I24: Leverandør (R), Kunde (C) | K24: Kundens prosjektgruppe | L24: fre 27.11.26 | M24: fre 27.11.26 | N24: 3 timer | P24: 0 | Q24: Gjennomgang av faglig kursinnhold og -oppgaver
B25: Kurs: Lederkurs (2 timer) | C25: - | D25: 4 | E25: 1 | F25: =IFERROR(AVERAGE(C25:D25)*_xlfn.XLOOKUP(E25,'Datavalidering (skjules)'!$I$7:$I$12,'Datavalidering (skjules)'!$J$7:$J$12),"") -> 4 | G25: Lav | H25: Opplæring | I25: Leverandør (R), Kunde (C) | K25: Kundens prosjektgruppe | L25: fre 27.11.26 | M25: fre 27.11.26 | N25: 2 timer | P25: 0 | Q25: Gjennomgang av faglig kursinnhold og -oppgaver
B26: Opplæring av Superbrukere
B27: Kurs: Administratorkurs (3 timer) | C27: - | D27: 6 | E27: 1 | F27: =IFERROR(AVERAGE(C27:D27)*_xlfn.XLOOKUP(E27,'Datavalidering (skjules)'!$I$7:$I$12,'Datavalidering (skjules)'!$J$7:$J$12),"") -> 6 | G27: Lav | H27: Opplæring | I27: Leverandør (R), Kunde (C) | K27: Kundens superbrukere | N27: 3 timer | P27: 0 | Q27: Gjennomgang av faglig kursinnhold og -oppgaver
B28: Kurs: Videregåendekurs (3 timer) | C28: - | D28: 6 | E28: 1 | F28: =IFERROR(AVERAGE(C28:D28)*_xlfn.XLOOKUP(E28,'Datavalidering (skjules)'!$I$7:$I$12,'Datavalidering (skjules)'!$J$7:$J$12),"") -> 6 | G28: Lav | H28: Opplæring | I28: Leverandør (R), Kunde (C) | K28: Kundens superbrukere | N28: 3 timer | P28: 0 | Q28: Gjennomgang av faglig kursinnhold og -oppgaver
B29: Kurs: Arkivarkurs (3 timer) | C29: - | D29: 6 | E29: 1 | F29: =IFERROR(AVERAGE(C29:D29)*_xlfn.XLOOKUP(E29,'Datavalidering (skjules)'!$I$7:$I$12,'Datavalidering (skjules)'!$J$7:$J$12),"") -> 6 | G29: Lav | H29: Opplæring | I29: Leverandør (R), Kunde (C) | K29: Kundens superbrukere | N29: 3 timer | P29: 0 | Q29: Gjennomgang av faglig kursinnhold og -oppgaver
B30: Generelle arbeidsmøter og opplæring
B31: Tema: Gjennomgang av konfigurasjonsdokument - Basispakke | C31: 8 | D31: 8 | E31: 1 | F31: =IFERROR(AVERAGE(C31:D31)*_xlfn.XLOOKUP(E31,'Datavalidering (skjules)'!$I$7:$I$12,'Datavalidering (skjules)'!$J$7:$J$12),"") -> 8 | G31: Medium | H31: Dokumentering og spesifisering | I31: Leverandør (R), Kunde (C) | K31: Kundens prosjektgruppe | L31: man 30.11.26 | M31: man 30.11.26 | N31: 1 time | P31: 0 | Q31: Kunden bør ha gjennomført administrator- og arkivarkurs først
B32: Tema: Gjennomgang API'er m/tredjepartsleverandør ift. Kundespesifikke integrasjoner | C32: 1 | D32: 4 | E32: 1 | F32: =IFERROR(AVERAGE(C32:D32)*_xlfn.XLOOKUP(E32,'Datavalidering (skjules)'!$I$7:$I$12,'Datavalidering (skjules)'!$J$7:$J$12),"") -> 2.5 | G32: Lav | H32: Generelle møter | I32: Leverandør (R), Kunde (C) | K32: Kundens prosjektgruppe | L32: man 30.11.26 | M32: man 30.11.26 | N32: 1 time | P32: 0 | Q32: Veiledning i hvordan Kunden kan opprette endepunkter, samt gjennomgang med tredjepart og Kunde for å identifisere nødvendige API'er
B33: Tema: Opplæring Flow | C33: 30 | D33: 30 | E33: 1 | G33: Lav | H33: Generelle møter | I33: Leverandør (R), Kunde (C) | K33: Kundens prosjektgruppe | L33: tir 01.12.26 | M33: tir 01.12.26 | N33: 1 time | P33: 0 | Q33: Veiledning i hvordan Kunden kan opprette endepunkter, samt gjennomgang med tredjepart og Kunde for å identifisere nødvendige API'er
B34: Tema: Opplæring Collect | C34: 30 | D34: 30 | E34: 1 | F34: 30 | G34: Lav | H34: Generelle møter | I34: Leverandør (R), Kunde (C) | K34: Kundens prosjektgruppe | L34: ons 02.12.26 | M34: ons 02.12.26 | N34: 1 time | P34: 0 | Q34: Veiledning i hvordan Kunden kan opprette endepunkter, samt gjennomgang med tredjepart og Kunde for å identifisere nødvendige API'er
B35: BASIC
B36: AD Sync | C36: 6 | D36: 24 | E36: 1 | F36: =IFERROR(AVERAGE(C36:D36)*_xlfn.XLOOKUP(E36,'Datavalidering (skjules)'!$I$7:$I$12,'Datavalidering (skjules)'!$J$7:$J$12),"") -> 15 | G36: Medium | H36: Installering | I36: Leverandør (R), Kunde (C) | K36: Kundens prosjektgruppe | L36: tors 03.12.26 | M36: tir 08.12.26 | P36: 0 | Q36: Arbeidsmøter for oppsett av modul avtales fortløpende. Kunden er selv ansvarlig for å signere evt. avtaler med tredjepart
A37: x | B37: Format Converter | C37: 2 | D37: 6 | E37: 1 | F37: =IFERROR(AVERAGE(C37:D37)*_xlfn.XLOOKUP(E37,'Datavalidering (skjules)'!$I$7:$I$12,'Datavalidering (skjules)'!$J$7:$J$12),"") -> 4 | G37: Lav | H37: Installering | I37: Leverandør (R), Kunde (C) | K37: Kundens prosjektgruppe | L37: tors 03.12.26 | M37: tir 08.12.26 | P37: 0 | Q37: Arbeidsmøter for oppsett av modul avtales fortløpende. Kunden er selv ansvarlig for å signere evt. avtaler med tredjepart
A38: x | B38: Archive Format Validator | C38: 2 | D38: 6 | E38: 1 | F38: =IFERROR(AVERAGE(C38:D38)*_xlfn.XLOOKUP(E38,'Datavalidering (skjules)'!$I$7:$I$12,'Datavalidering (skjules)'!$J$7:$J$12),"") -> 4 | G38: Lav | H38: Installering | I38: Leverandør (R), Kunde (C) | K38: Kundens prosjektgruppe | L38: tors 03.12.26 | M38: tir 08.12.26 | P38: 0 | Q38: Arbeidsmøter for oppsett av modul avtales fortløpende. Kunden er selv ansvarlig for å signere evt. avtaler med tredjepart
B39: DIGITAL COMMUNICATION
A40: x | B40: Dispatch Adapter: DPI | C40: 2 | D40: 6 | E40: 1 | G40: Medium | H40: Installering | I40: Leverandør (R), Kunde (C) | K40: Kundens prosjektgruppe | L40: tors 03.12.26 | M40: tir 08.12.26 | P40: 0 | Q40: Arbeidsmøter for oppsett av modul avtales fortløpende. Kunden er selv ansvarlig for å signere evt. avtaler med tredjepart
A41: x | B41: Dispatch Adapter: eFormidling | C41: 12 | D41: 24 | E41: 1 | G41: Medium | H41: Installering | I41: Leverandør (R), Kunde (C) | K41: Kundens prosjektgruppe | L41: tors 03.12.26 | M41: tir 08.12.26 | P41: 0 | Q41: Arbeidsmøter for oppsett av modul avtales fortløpende. Kunden er selv ansvarlig for å signere evt. avtaler med tredjepart
...

Sheet Milepæler
B2: Implementeringsprosjekt - Standardmilepæler
B4: ID | C4: Milepælsbeskrivelse | D4: Kommentar
B5: MP0 | C5: Kontrakten er signert
B6: MP1 | C6: Prosjektet er igangsatt | D6: Dette for å tydeliggjøre at vi nå kan føre tid på prosjektet
B7: MP2 | C7: Omforent fremdriftsplan er godkjent
B8: MP3 | C8: Avtalt miljø er klart for funksjonelt oppsett og verifisering | D8: SaaS begynner 50%, dersom avtalt.
B9: MP4 | C9: Konfigurasjonsdokumentet er godkjent
B10: MP5 | C10: Løsningen er klar for Kundens Godkjenningsprøve
B11: MP6 | C11: Perioden for Godkjenningsprøven er utløpt og Løsningen er godkjent iht. akseptansekriteriene | D11: Kunden må få Leveransemelding om at Leveringsdagen skjer påfølgende virkedag og SaaS begynner 100%.
B12: MP7 | C12: Løsningen er driftsatt og tilgjengeliggjort for sluttbrukerne
B13: MP8 | C13: Prosjektet er avsluttet og overlevert til forvaltning

Sheet Datavalidering (skjules)
B3: Ja | C3: Lav
B4: Nei | C4: Medium
C5: Høy
I6: Miljøer | J6: Multipliseres
I7: 1 | J7: 1
B8: Passord (låste celler): P360 | I8: 2 | J8: 1.5
I9: 3 | J9: 2
B13: Kategorier | C13: Beskrivelse | E13: Risikokategori | F13: Beskrivelse
B14: Prosjektledelse | C14: Administrasjon, økonomi, SG-møter, statusmøter | E14: Budsjett | F14: Administrasjon, økonomi, SG-møter, statusmøter
B15: Analysering | E15: Tidsplan
B16: Dokumentering og spesifisering | E16: Teknologi
B17: Utvikling | E17: Informasjon
B18: Implementering | E18: Sikkerhet
B19: Migrering | E19: Kvalitet
B20: Installering | E20: Prosjektplan
B21: Testing | E21: Leveranse
B22: Rådgivning | E22: Juridisk
B23: Opplæring
B24: Generelle møter

Sheet Opsjoner og tilleggsaktiviteter
A1: Opsjoner og tilleggsaktiviteter - Aktiviteter | D1: Estimater (internt) | S1: Prosjektleder | T1: Rådgiver | U1: Deployer | V1: Utvikler | W1: Support | X1: Prosjekteier
A2: Foreslått fase | B2: Aktiviteter | D2: Obligatorisk | E2: Min (timer) | F2: Max (timer) | G2: Budsjett (timer) | H2: Risikonivå | I2: Kategori | J2: Ansvarlig | K2: Navngitt ansvarlig | L2: Andre deltakere | M2: Start | N2: Slutt | O2: Varighet | P2: Tidspunkt | Q2: Fullført | R2: Aktivitetsbeskrivelse | S2: Leverandørens ansvarsfordeling
A3: ∞
B4: Ekstra statusmøter | D4: Nei | G4: =IFERROR(AVERAGE(E4:F4),"") | H4: Lav | I4: Prosjektledelse | J4: Leverandør | L4: Kundens prosjektgruppe | Q4: 0 | S4: R | T4: C/I | U4: C/I | V4: C/I | X4: A
B5: Ekstra arbeidsmøter | D5: Nei | G5: =IFERROR(AVERAGE(E5:F5),"") | H5: Lav
B6: Utvikling av maler iht. avtale | D6: Nei | G6: =IFERROR(AVERAGE(E6:F6),"") | H6: Medium | Q6: 0
A7: SG | B7: Ekstra styringsgruppemøte | D7: Nei | E7: 1 | F7: 2 | G7: =IFERROR(AVERAGE(E7:F7),"") -> 1.5 | H7: Lav | I7: Prosjektledelse | J7: Leverandør | L7: Kundens styringsgruppe | Q7: 0 | R7: Ikke-fakturerbart?
B8: Bistand utover Leveransensens inkluderte timer | D8: Nei | G8: =IFERROR(AVERAGE(E8:F8),"") | H8: Lav | Q8: 0 | R8: Omfang og fakturering avtales med Kunden (enten via EO eller løpende timer) | S8: A | T8: R | U8: R | V8: R
B9: Leverandørens bistand med installasjon av klassifikasjonskoder (K-koder) | D9: Nei | G9: =IFERROR(AVERAGE(E9:F9),"") | H9: Medium | Q9: 0 | R9: Normalt en fastpris | T9: R
B10: Leverandørens bistand med installasjon av arkivnøkler | D10: Nei | G10: =IFERROR(AVERAGE(E10:F10),"") | H10: Medium
D11: Nei | G11: =IFERROR(AVERAGE(E11:F11),"") | H11: Lav
B12: Opplæring og innføring | G12: =IFERROR(AVERAGE(E12:F12),"")
B13: Floor Walking | D13: Nei | E13: - | F13: 1 | G13: =IFERROR(AVERAGE(E13:F13),"") -> 1 | H13: Lav | Q13: 0 | R13: Varighet etter avtale | S13: I/A | T13: R
B14: Train the Trainer | D14: Nei | E14: 12 | F14: 18 | G14: =IFERROR(AVERAGE(E14:F14),"") -> 15 | H14: Lav | O14: 2 dager | Q14: 0 | S14: I/A | T14: R
B15: Spørretime (digitalt) | D15: Nei | E15: 1 | F15: 4 | G15: =IFERROR(AVERAGE(E15:F15),"") -> 2.5 | H15: Medium | O15: 1 time | Q15: 0 | S15: I/A | T15: R
B16: eLæring | D16: Nei | G16: =IFERROR(AVERAGE(E16:F16),"") | H16: Lav | Q16: 0 | S16: I/A | T16: R
B17: Ekstra miljø | G17: =IFERROR(AVERAGE(E17:F17),"") | R17: Når det skal leveres mer enn ett miljø i prosjektet. Modulkonfig kommer i tillegg.
B18: Administrasjon (utsendelse av velkomstbrev, booking, GW12 m.m.) | D18: Nei | E18: 2 | F18: 4 | G18: =IFERROR(AVERAGE(E18:F18),"") -> 3 | H18: Lav | Q18: 0
B19: Installering av ekstra miljø + verifisering av tilkobling | D19: Nei | E19: 2 | F19: 4 | G19: =IFERROR(AVERAGE(E19:F19),"") -> 3 | H19: Lav | Q19: 0
B20: Import av DB-kopi | D20: Nei | E20: 2 | F20: 6 | G20: =IFERROR(AVERAGE(E20:F20),"") -> 4 | H20: Lav | Q20: 0
B21: Bistand under Kundens verifisering | D21: Nei | E21: 2 | F21: 10 | G21: =IFERROR(AVERAGE(E21:F21),"") -> 6 | H21: Medium | Q21: 0
Q22: 0
B23: OnPrem-aktiviteter | R23: Når prosjektet ikke er Cloud.
B24: Etablering av lokale miljøer (Internt, utvikling, test) | D24: Ja | G24: =IFERROR(AVERAGE(E24:F24),"") | H24: Lav | Q24: 0
B25: Teknisk verifikasjon av lokale miljøer | D25: Ja | G25: =IFERROR(AVERAGE(E25:F25),"") | H25: Lav | Q25: 0
D26: Nei | G26: =IFERROR(AVERAGE(E26:F26),"") | H26: Lav | Q26: 0
D27: Nei | G27: =IFERROR(AVERAGE(E27:F27),"") | H27: Lav | Q27: 0
D28: Nei | G28: =IFERROR(AVERAGE(E28:F28),"") | H28: Lav | Q28: 0
A29: FASE 1 | G29: =IFERROR(AVERAGE(E29:F29),"")
D30: Nei | G30: =IFERROR(AVERAGE(E30:F30),"") | H30: Lav | Q30: 0
D31: Nei | G31: =IFERROR(AVERAGE(E31:F31),"") | H31: Lav | Q31: 0
A32: FASE 2 | G32: =IFERROR(AVERAGE(E32:F32),"")
B33: Møte: Gjennomgang av AD Sync-oppsett | D33: Ja | G33: =IFERROR(AVERAGE(E33:F33),"") | H33: Lav | Q33: 0
B34: Leverandøren er tilgjengelig for Kunden med avklaringer og evt. Justeringer | D34: Nei | G34: =IFERROR(AVERAGE(E34:F34),"") | H34: Lav | Q34: 0 | R34: Relatert til konfigdokumentet, faktureres på løpende timer
B35: Generelle arbeidsmøter | G35: =IFERROR(AVERAGE(E35:F35),"")
B36: Tema: Gjennomgang av Løsningens standard Møte og utvalg-maler | D36: Nei | G36: =IFERROR(AVERAGE(E36:F36),"") | H36: Lav | Q36: 0
B37: Tema: Gjennomgang API'er m/tredjepartsleverandør ift. Kundespesifikke integrasjoner | D37: Nei | G37: =IFERROR(AVERAGE(E37:F37),"") | H37: Lav | Q37: 0
B38: Tema: Informasjonsmøte om arkivnøkler | D38: Nei | G38: =IFERROR(AVERAGE(E38:F38),"") | H38: Lav | Q38: 0
B39: Tema: Håndtering av åpne saker (MCUT) | D39: Nei | G39: =IFERROR(AVERAGE(E39:F39),"") | H39: Lav | Q39: 0
B40: Opplæring av prosjektgruppe | G40: =IFERROR(AVERAGE(E40:F40),"")
...
