Workbook
Name _Toc233296974: Evalueringshieraki!$B$4
Name _Toc233296977: Evalueringshieraki!$B$5
Name _Toc233296984: 'Production Plan'!$E$13
Name _Toc233296986: 'Production Plan'!$E$19
Name _Toc233296997: 'Production Plan'!$E$71
Name _Toc233297011: 'Production Plan'!$D$173

Sheet Production Plan
A1: # | B1: ReqID | C1: Document | D1: Section (Headline) | E1: Subsection | F1: Requirement title | G1: Requirement | H1: Besvarelsesvejledning | I1: Requirement type | J1: Action | K1: Faktor | L1: Kvalitetskriterium | M1: Vægt (point) | N1: Round #1 | O1: Responsible | P1: Reviewer | Q1: Module | R1: Can we meet the requirement? | S1: Comment | T1: Commitment needed? | U1: Risk Element? | V1: Cost Driver | W1: Link to answer document | X1: Status (phase) | Y1: Status (%)
A2: 1 | B2: 4.1.1. | C2: Bilag 2 - Kravspecifikation | D2: Tidsplan (15%) | E2: Implementering og tidsplan | F2: Implementeringsplan | G2: Implementeringsplan Leverandøren skal beskrive sin samlede plan for implementering af Løsningen hos Kunden. Beskrivelsen skal omfatte punkterne i Bilag 11 Dokumentations, pkt. 7: Det vægtes positivt, at:  Leverandøren demonstrerer en klar forståelse for Kundens it-miljø og de tekniske forudsætninger, herunder relevante integrationer, snitflader, datamigrering og sikkerhedsmæssige forhold.  Tidsplanen afspejler Kundens organisation og implementeringens kompleksitet.  Leverandøren giver en sammenhængende og realistisk faseopdeling af implementeringsforløbet med klare milepæle og godkendelsespunkter, der sikrer, at Kunden kan godkende afslutning af en fase, før næste fase igangsættes.  Leverandøren tydeligt beskriver kendte risici og faldgruber i implementeringsforløbet, samt konkrete mitigerende tiltag.  At tidsplanen tager højde for, at Ordregiver har en løbende drift der skal varetages og perioder med begrænsede ressourcer | H2: Informationskravet besvares ved at Leverandøren vedhæfter eget bilag og udfylder tabel 5.4. (Detaljeret tidsplan) i Bilag 1 - Implementering | I2: IK - Informationskrav | J2: =IF(I2="IK - Informationskrav","Answer",(IF(I2="K - Konkurrencekrav","Check",(IF(I2="MK - Mindstekrav","Verify",""))))) -> Answer | K2: 2 | L2: 1 | M2: 4 | O2: Cristina | S2: Evt. koordiner med Kaare AOP: OBS at Eskalering sker i overensstemmelse med den i bilag 1 – Implementering gældende samarbejdsorganisation, f.eks. driftsgruppen eller jf. Kontraktens afsnit 31 vedr. Tvister. - denne skal derfor tage højde for dette. | W2: Bilag 2 - 4.1.1 - Implementeringsplan.docx | X2: Not Started | Y2: =IF(X2="Not Started",0%,IF(X2="Read",1%,IF(X2="Started",50%,IF(X2="Ready for review",70%,IF(X2="Reviewed - Content",80%,IF(X2="Reviewed - Format",90%,IF(X2="Done",100%,""))))))) -> 0
A3: 2 | B3: 4.2.1. | C3: Bilag 2 - Kravspecifikation | D3: Tidsplan (15%) | E3: Tidsplan for optioner | F3: Tidsplan for optioner | G3: Tidsplan for optioner Leverandøren bedes redegøre for hvornår optionerne, jf. punkt 5.4. (5.4.1. & 5.4.2.) i nærværende bilag, kan forventes færdigleveret efter Kunden har kaldt optioner. Leverandøren skal indregne alle relevante faktorer, såsom udvikling af integrationen, men også forhold hos Kunden som Leverandøren er bekendt med ud fra nærværende materiale samt tilhørende bilag. Det vægter positivt at - optionen tilbydes til levering så tæt på Overtagelsesdagen, som muligt. - tidligste dato for Kundens kald af optionen er så tæt på Kontraktindgåelsesdatoen, som muligt. | H3: Informationskravet besvares ved at Leverandøren vedhæfter eget bilag. | I3: IK - Informationskrav | J3: =IF(I3="IK - Informationskrav","Answer",(IF(I3="K - Konkurrencekrav","Check",(IF(I3="MK - Mindstekrav","Verify",""))))) -> Answer | K3: 1 | L3: 1 | M3: 8 | O3: Cristina | W3: Bilag 2 - 4.2.1 - Tidsplan for optioner.docx | X3: Not Started | Y3: =IF(X3="Not Started",0%,IF(X3="Read",1%,IF(X3="Started",50%,IF(X3="Ready for review",70%,IF(X3="Reviewed - Content",80%,IF(X3="Reviewed - Format",90%,IF(X3="Done",100%,""))))))) -> 0
A4: 3 | B4: 5.1.1.1. | C4: Bilag 2 - Kravspecifikation | D4: Generelle krav | E4: Test og prøver | F4: Prøveplan | G4: Prøveplan Leverandøren skal beskrive teststrategien og redegøre for hvorledes aktiviteterne bedst påviser, at kravene i Bilag 2 (Kravspecifikation) efterleves. Det vægtes positivt, at:  Leverandøren beskriver teststrategien på en måde, så den tydelig beskriver, hvilken teststrategi Leverandøren anvender for at sikre, at Løsningen lever op til Kundens krav  Leverandøren beskriver eksempler på prøveplaner og testrapport med angivelse af ansvarsfordeling, testprincipper, metoder og værktøjer mm.  Leverandøren beskriver hvordan og i hvilken grad testcases udledes af Kundens krav  Hvordan dokumenteres og sikres kvalitet og stabilitet under test og prøver, f.eks. ved brug af dedikerede testværktøjer såsom Azure DevOps el.lign. | H4: Informationskravet besvares ved at Leverandøren vedhæfter eget bilag. | I4: IK - Informationskrav | J4: =IF(I4="IK - Informationskrav","Answer",(IF(I4="K - Konkurrencekrav","Check",(IF(I4="MK - Mindstekrav","Verify",""))))) -> Answer | K4: 2 | L4: 2 | M4: =Evalueringshieraki!$Q$16 -> 0.97087379 | O4: Cristina | W4: Bilag 2 - 5.1.1.1 - Prøveplan.docx | X4: Not Started | Y4: =IF(X4="Not Started",0%,IF(X4="Read",1%,IF(X4="Started",50%,IF(X4="Ready for review",70%,IF(X4="Reviewed - Content",80%,IF(X4="Reviewed - Format",90%,IF(X4="Done",100%,""))))))) -> 0
A5: 4 | B5: 5.1.2.1. | C5: Bilag 2 - Kravspecifikation | D5: Generelle krav | E5: Uddannelse | F5: Uddannelse | G5: Uddannelse Leverandøren skal levere en uddannelsesplan, der medfører at de forskellige typer af Brugere er i stand til at anvende Systemet ved idriftsættelse. Besvarelsen bør tage udgangspunkt i nærværende krav samt Bilag 1 (Implementering) pkt. 7 og Bilag 11 (Dokumentation) pkt. 7. Leverandøren skal i besvarelsen redegøre for deres undervisningstilbud i Løsningen, herunder de(n) tilknyttede instruktørers undervisningserfaring. Det vægtes positivt, at: - at der for de enkelte kurser er klare, konkrete og realistiske læringsmål - at det viser organiseringen af den tilbudte undervisning - at uddannelsen i videst muligt omfang tager afsæt i de forskellige Brugeres faglige profil og relevante arbejdsgange - at kurserne i videst muligt omfang behandler Kundens centrale arbejdsgange - at instruktører er erfarne i at undervise og kender målgruppens hverdag | H5: Informationskravet besvares i Leverandørens eget bilag. | I5: IK - Informationskrav | J5: =IF(I5="IK - Informationskrav","Answer",(IF(I5="K - Konkurrencekrav","Check",(IF(I5="MK - Mindstekrav","Verify",""))))) -> Answer | K5: 1 | L5: 3 | M5: 30 | O5: Anton | P5: Tony, Cristian | W5: Bilag 2 - 5.1.2.1 - Uddannelse.docx | X5: Started | Y5: =IF(X5="Not Started",0%,IF(X5="Read",1%,IF(X5="Started",50%,IF(X5="Ready for review",70%,IF(X5="Reviewed - Content",80%,IF(X5="Reviewed - Format",90%,IF(X5="Done",100%,""))))))) -> 0.5
A6: 5 | B6: 5.1.3.1. | C6: Bilag 2 - Kravspecifikation | D6: Generelle krav | E6: Data migrering og konvertering | F6: Migreringsplan | G6: Migreringsplan Leverandøren skal levere en migreringsplan og bedes redegøre for hvordan migrering fra Kundens eksisterende system til Systemet vil forløbe med udgangspunkt i kravene i Bilag 1 Implementering, pkt. 6. Migreringsplanens udformning og indhold skal følge Bilag 11 (Dokumentation) pkt. 7. Det vægter positivt at: - dataintegritet af migreringen valideres løbende, f.eks. gennem checksum, tests og overvågning. - data håndteres sikkert, f.eks. ved kryptering. - data migreres og konverteres så automatisk som muligt. - der er indtænkt processer for håndtering af fejl - datamigrering påvirker Brugerens arbejde mindst muligt - besvarelsen indeholder flere konkrete eksempler og detaljer vedr. migreringsaktiviteter. | H6: Informationskravet besvares i Leverandørens eget bilag. | I6: IK - Informationskrav | J6: =IF(I6="IK - Informationskrav","Answer",(IF(I6="K - Konkurrencekrav","Check",(IF(I6="MK - Mindstekrav","Verify",""))))) -> Answer | K6: 2 | L6: 1 | M6: 8 | O6: Kaare | S6: Koordiner med Cristina. | W6: Bilag 2 - 5.1.3.1 - Migreringsplan.docx | X6: Not Started | Y6: =IF(X6="Not Started",0%,IF(X6="Read",1%,IF(X6="Started",50%,IF(X6="Ready for review",70%,IF(X6="Reviewed - Content",80%,IF(X6="Reviewed - Format",90%,IF(X6="Done",100%,""))))))) -> 0
A7: 6 | B7: 5.2.1.1. | C7: Bilag 2 - Kravspecifikation | D7: Funktionelle krav | E7: Journalisering, dokumenthåndtering og sagsoverblik | F7: Opmærkning af sager og dokumenter | G7: Opmærkning af sager og dokumenter Både sager og dokumenter skal kunne opmærkes, struktureres eller tildeles ”tags” på baggrund af emne, type, kategori m.m. som gør det lettere at søge, sortere og få overblik over data. Løsningen skal give mulighed for sortering på fx indsendelser, dato, emne, teknisk kapitel (fra BOM), fase (fra BOM, bl.a. 'ansøgning', 'under arbejde', 'efter endt arbejde' osv.). Det vægtes positivt, at Leverandøren i sin besvarelse demonstrerer, at Løsningen understøtter:  at data og dokumentation automatisk inddeles i en logisk og overskuelig struktur på sagen  at sagsbehandlere fleksibelt kan tilpasse strukturen til den enkelte sag eller sagstype  at "tag"-funktionen giver mulighed for at tagge på tværs af evt. dokumentstruktur og dokumenttyper  at sortering kan foretages på flere parametre samtidigt (fx fase og dato kombineret)  at sortering og inddeling er konsistent på tværs af sager og sagstyper, så der sikres ensartethed i sagsbehandlingen  at nye sorteringsparametre kan tilføjes uden behov for systemudvikling  At man hurtigt kan se, hvad der er sagsbehandlet og hvad der udestår. | I7: IK - Informationskrav | J7: =IF(I7="IK - Informationskrav","Answer",(IF(I7="K - Konkurrencekrav","Check",(IF(I7="MK - Mindstekrav","Verify",""))))) -> Answer | K7: 1 | L7: 2 | M7: =Evalueringshieraki!$P$16 -> 0.48543689 | O7: Bjørn Henrik | W7: Bilag 2 - 5.2.1.1 - Opmærkning af sager og dokumenter.docx | X7: Not Started | Y7: =IF(X7="Not Started",0%,IF(X7="Read",1%,IF(X7="Started",50%,IF(X7="Ready for review",70%,IF(X7="Reviewed - Content",80%,IF(X7="Reviewed - Format",90%,IF(X7="Done",100%,""))))))) -> 0
A8: 7 | B8: 5.2.1.2. | C8: Bilag 2 - Kravspecifikation | D8: Funktionelle krav | E8: Journalisering, dokumenthåndtering og sagsoverblik | F8: Konfliktløsning | G8: Konfliktløsning Løsningen skal kunne initiere/kalde en konfliktsøgning der foretages af andet system. Det være sig GIS, en robot eller AI løsning. Initieringen kan være på baggrund af en matrikel, BFE-nr., adresse eller lignende (som altså kan medsendes i kaldet til det eksterne system) Det vægtes positivt, at Leverandøren i sin besvarelse demonstrerer, at Løsningen understøtter:  at konfliktsøgningen kan sættes til at køre automatisk ved oprettelse af nye sager  at sagsbehandler adviseres tydeligt, hvis der identificeres konflikter  at det angives hvis der er adressebeskyttelse eller fortrolighed  at konfliktsøgningen kan gemmes som et dokument på sagen, meget gerne automatisk | I8: IK - Informationskrav | J8: =IF(I8="IK - Informationskrav","Answer",(IF(I8="K - Konkurrencekrav","Check",(IF(I8="MK - Mindstekrav","Verify",""))))) -> Answer | K8: 1 | L8: 2 | M8: =Evalueringshieraki!$P$16 -> 0.48543689 | O8: Arve | T8: Yes | W8: Bilag 2 - 5.2.1.2 - Konfliktløsning.docx | X8: Not Started | Y8: =IF(X8="Not Started",0%,IF(X8="Read",1%,IF(X8="Started",50%,IF(X8="Ready for review",70%,IF(X8="Reviewed - Content",80%,IF(X8="Reviewed - Format",90%,IF(X8="Done",100%,""))))))) -> 0
A9: 8 | B9: 5.2.1.3. | C9: Bilag 2 - Kravspecifikation | D9: Funktionelle krav | E9: Journalisering, dokumenthåndtering og sagsoverblik | F9: - | G9: Smidig journalisering af data/dokumentation på sagen fx ved ”drag & drop” (BOM/mail/blanketter/erhvervsportal). Dog også mulighed for manuel upload til journalisering. | I9: K - Konkurrencekrav | J9: =IF(I9="IK - Informationskrav","Answer",(IF(I9="K - Konkurrencekrav","Check",(IF(I9="MK - Mindstekrav","Verify",""))))) -> Check | K9: 1 | L9: 2 | M9: =Evalueringshieraki!$P$16 -> 0.48543689 | O9: Arve | R9: 1. Fully met | S9: Drag'n'drop from BOM? - Har BOM automatisk journalføring i vår BOM integrasjon (Må løftes inn i P&B) -Har skjemaimport, men må estimeres. | T9: Yes | X9: Not Started | Y9: =IF(X9="Not Started",0%,IF(X9="Read",1%,IF(X9="Started",50%,IF(X9="Ready for review",70%,IF(X9="Reviewed - Content",80%,IF(X9="Reviewed - Format",90%,IF(X9="Done",100%,""))))))) -> 0
A10: 9 | B10: 5.2.1.4. | C10: Bilag 2 - Kravspecifikation | D10: Funktionelle krav | E10: Journalisering, dokumenthåndtering og sagsoverblik | F10: - | G10: Løsningen skal kunne give et samlet overblik over tidligere og nuværende sager. | I10: K - Konkurrencekrav | J10: =IF(I10="IK - Informationskrav","Answer",(IF(I10="K - Konkurrencekrav","Check",(IF(I10="MK - Mindstekrav","Verify",""))))) -> Check | K10: 1 | L10: 2 | M10: =Evalueringshieraki!$P$16 -> 0.48543689 | O10: Anton | R10: 1. Fully met | X10: Ready for review | Y10: =IF(X10="Not Started",0%,IF(X10="Read",1%,IF(X10="Started",50%,IF(X10="Ready for review",70%,IF(X10="Reviewed - Content",80%,IF(X10="Reviewed - Format",90%,IF(X10="Done",100%,""))))))) -> 0.7
A11: 10 | B11: 5.2.1.5. | C11: Bilag 2 - Kravspecifikation | D11: Funktionelle krav | E11: Journalisering, dokumenthåndtering og sagsoverblik | F11: - | G11: Det skal være muligt at søge på og i sagernes dokumenter. | I11: K - Konkurrencekrav | J11: =IF(I11="IK - Informationskrav","Answer",(IF(I11="K - Konkurrencekrav","Check",(IF(I11="MK - Mindstekrav","Verify",""))))) -> Check | K11: 1 | L11: 2 | M11: =Evalueringshieraki!$P$16 -> 0.48543689 | O11: Anton | R11: 1. Fully met | X11: Ready for review | Y11: =IF(X11="Not Started",0%,IF(X11="Read",1%,IF(X11="Started",50%,IF(X11="Ready for review",70%,IF(X11="Reviewed - Content",80%,IF(X11="Reviewed - Format",90%,IF(X11="Done",100%,""))))))) -> 0.7
A12: 11 | B12: 5.2.1.6. | C12: Bilag 2 - Kravspecifikation | D12: Funktionelle krav | E12: Journalisering, dokumenthåndtering og sagsoverblik | F12: Understøttelse af Elektronisk Sags- og Dokumenthåndtering | G12: Understøttelse af Elektronisk Sags- og Dokumenthåndtering Leverandøren bedes redegøre for i hvilket omfang Løsningen kan understøtte Brugeren i at løfte journaliseringspligt, jf. offentliglovens § 15. Det vægter positivt at: - Kunden kan opsætte regler for hvem der kan redigere, slette fejloprettede sager eller genåbne afsluttede sager. - Løsningen understøtter automatisk journalisering - Dokumenter modtaget på sagerne journaliseres. - Notater nemt kan journaliseres af Brugeren. - Kommunikation der initieres eller modtages af systemet automatisk journaliseres på sagen. - Journaliserede elementer er tydeligt dateret. - Journaliseret indhold er opmærket så det er tydeligt hvad indholdet er. - Mulighed for KLE-opmærkning af sager | I12: IK - Informationskrav | J12: =IF(I12="IK - Informationskrav","Answer",(IF(I12="K - Konkurrencekrav","Check",(IF(I12="MK - Mindstekrav","Verify",""))))) -> Answer | K12: 2 | L12: 2 | M12: =Evalueringshieraki!$Q$16 -> 0.97087379 | O12: Anita | W12: Bilag 2 - 5.2.1.6 - Understøttelse af Elektronisk Sags- og Dokumenthåndtering.docx | X12: Read | Y12: =IF(X12="Not Started",0%,IF(X12="Read",1%,IF(X12="Started",50%,IF(X12="Ready for review",70%,IF(X12="Reviewed - Content",80%,IF(X12="Reviewed - Format",90%,IF(X12="Done",100%,""))))))) -> 0.01
A13: 12 | B13: 5.2.2.1. | C13: Bilag 2 - Kravspecifikation | D13: Funktionelle krav | E13: Hentning og opdatering af ejendomsdata | F13: Ejendomsdata | G13: IK Ejendomsdata Løsningen skal hente og anvende nedenstående ejendomsdata fra Datafordeleren:  Adresser inklusive vejnavn, husnummer, postnummer og postdistrikt.  Bygningsnummer.  Bestemt fast ejendomsnummer (herefter ”BFE”) for grund, ejerlejlighed og Bygning på fremmed grund (herefter ”BPFG”)  Matrikelnummer og ejerlav.  Ejerlejlighedsnummer.  Bygningens anvendelseskode (fx parcelhus, erhverv, institution).  Bygningens opførelses år.  Bebygget areal og samlet bygningsareal.  Antal bolig- og erhvervsenheder.  Energikilde og varmeinstallation.  Ejerforhold fra Ejerfortegnelsen (herefter ”EJF”), herunder oplysninger om hvem der råder over fast ejendom.  Ejendomsbeliggenhedsregistret (herefter ”EBR”), herunder referencer mellem ejendomme og adresser/beliggenhedsbetegnelser. Løsningens skal sikre opdatering af ejendomsdata på alle verserende sager mindst én gang i døgnet, og både historiske og aktuelle data skal vises på sagerne. Ejendomsdata skal være søgbare - både enkeltvis og i kombination med øvrige data. Det vægtes positivt at  at sagsbehandlere kan søge på alle ejendomsdata og finde både aktuelle og historiske sager, enkeltvis eller i kombination med øvrige søgekriterier, herunder ved brug af AND/OR-logik eller avancerede filtre  at ejendomsdata kan danne udgangspunkt for filtrering, lister og sortering af fremsøgte sager, samt at søgeresultater kan eksporteres til gængse formater (fx Excel, CSV)  at ejendomsdata fremgår samlet og overskueligt på den enkelte sag  at sagsbehandlere, teams og enheder notificeres automatisk, når ejendomsdata ændres på verserende sager  at ændringer i ejendomsdata tilføjes sagen med angivelse af tidsstempel og brugeridentitet, uden at tidligere data slettes | I13: IK - Informationskrav | J13: =IF(I13="IK - Informationskrav","Answer",(IF(I13="K - Konkurrencekrav","Check",(IF(I13="MK - Mindstekrav","Verify",""))))) -> Answer | K13: 1 | L13: 2 | M13: =Evalueringshieraki!$P$16 -> 0.48543689 | O13: Axel | R13: 1. Fully met | S13: Vi kan det allerede i eDoc, en stor del er (vist) allerede flyttet til P360 | T13: Yes | W13: Bilag 2 - 5.2.2.1 - Ejendomsdata.docx | X13: Ready for review | Y13: =IF(X13="Not Started",0%,IF(X13="Read",1%,IF(X13="Started",50%,IF(X13="Ready for review",70%,IF(X13="Reviewed - Content",80%,IF(X13="Reviewed - Format",90%,IF(X13="Done",100%,""))))))) -> 0.7
A14: 13 | B14: 5.2.3.1. | C14: Bilag 2 - Kravspecifikation | D14: Funktionelle krav | E14: Registrering af ejere og interessenter | F14: - | G14: Løsningen understøtter registrering af skift af ansøger eller ejer (medejer, historisk ansøger eller ejer) og øvrige interessenter. | I14: K - Konkurrencekrav | J14: =IF(I14="IK - Informationskrav","Answer",(IF(I14="K - Konkurrencekrav","Check",(IF(I14="MK - Mindstekrav","Verify",""))))) -> Check | K14: 1 | L14: 2 | M14: =Evalueringshieraki!$P$16 -> 0.48543689 | O14: Axel | S14: Kan vi i eDoc, ved Aalborg har meldt en bug ind på det, vil kræve merge af kode samt bugfix | T14: Yes | X14: Ready for review | Y14: =IF(X14="Not Started",0%,IF(X14="Read",1%,IF(X14="Started",50%,IF(X14="Ready for review",70%,IF(X14="Reviewed - Content",80%,IF(X14="Reviewed - Format",90%,IF(X14="Done",100%,""))))))) -> 0.7
A15: 14 | B15: 5.2.3.2. | C15: Bilag 2 - Kravspecifikation | D15: Funktionelle krav | E15: Registrering af ejere og interessenter | F15: - | G15: Løsningen understøtter registrering af eventuelt flere matrikler på sagen, som skal bruges af sagsbehandlerne. | I15: K - Konkurrencekrav | J15: =IF(I15="IK - Informationskrav","Answer",(IF(I15="K - Konkurrencekrav","Check",(IF(I15="MK - Mindstekrav","Verify",""))))) -> Check | K15: 1 | L15: 2 | M15: =Evalueringshieraki!$P$16 -> 0.48543689 | O15: Bjørn Henrik | R15: 1. Fully met | X15: Not Started | Y15: =IF(X15="Not Started",0%,IF(X15="Read",1%,IF(X15="Started",50%,IF(X15="Ready for review",70%,IF(X15="Reviewed - Content",80%,IF(X15="Reviewed - Format",90%,IF(X15="Done",100%,""))))))) -> 0
A16: 15 | B16: 5.2.3.3. | C16: Bilag 2 - Kravspecifikation | D16: Funktionelle krav | E16: Registrering af ejere og interessenter | F16: - | G16: Løsningen understøtter opslag på sager på matriklen (afsluttede og igangværende) | I16: K - Konkurrencekrav | J16: =IF(I16="IK - Informationskrav","Answer",(IF(I16="K - Konkurrencekrav","Check",(IF(I16="MK - Mindstekrav","Verify",""))))) -> Check | K16: 1 | L16: 2 | M16: =Evalueringshieraki!$P$16 -> 0.48543689 | O16: Anton | R16: 1. Fully met | X16: Ready for review | Y16: =IF(X16="Not Started",0%,IF(X16="Read",1%,IF(X16="Started",50%,IF(X16="Ready for review",70%,IF(X16="Reviewed - Content",80%,IF(X16="Reviewed - Format",90%,IF(X16="Done",100%,""))))))) -> 0.7
A17: 16 | B17: 5.2.3.4. | C17: Bilag 2 - Kravspecifikation | D17: Funktionelle krav | E17: Registrering af ejere og interessenter | F17: - | G17: Opslag på interessenten for at finde øvrige oprettede sager ved eks. mistet certifikat for rådgivere. | I17: K - Konkurrencekrav | J17: =IF(I17="IK - Informationskrav","Answer",(IF(I17="K - Konkurrencekrav","Check",(IF(I17="MK - Mindstekrav","Verify",""))))) -> Check | K17: 1 | L17: 2 | M17: =Evalueringshieraki!$P$16 -> 0.48543689 | O17: Anton | R17: 1. Fully met | X17: Ready for review | Y17: =IF(X17="Not Started",0%,IF(X17="Read",1%,IF(X17="Started",50%,IF(X17="Ready for review",70%,IF(X17="Reviewed - Content",80%,IF(X17="Reviewed - Format",90%,IF(X17="Done",100%,""))))))) -> 0.7
A18: 17 | B18: 5.2.3.5. | C18: Bilag 2 - Kravspecifikation | D18: Funktionelle krav | E18: Registrering af ejere og interessenter | F18: Interessent roller | G18: Interessent roller Sagsbehandlerne har brug for at kunne notere hvilken rolle de enkelte interessenter har/har haft på sagen. Leverandøren bedes redegøre for hvordan rollerne til interessenter kan tildeles og evt. ændres. Det vægtes positivt at - kunden kan anvende faste kategorier - at interessenter kan fremsøges på baggrund af deres roller | I18: IK - Informationskrav | J18: =IF(I18="IK - Informationskrav","Answer",(IF(I18="K - Konkurrencekrav","Check",(IF(I18="MK - Mindstekrav","Verify",""))))) -> Answer | K18: 1 | L18: 2 | M18: =Evalueringshieraki!$P$16 -> 0.48543689 | O18: Anita | W18: Bilag 2 - 5.2.3.5 - Interessent roller.docx | X18: Not Started | Y18: =IF(X18="Not Started",0%,IF(X18="Read",1%,IF(X18="Started",50%,IF(X18="Ready for review",70%,IF(X18="Reviewed - Content",80%,IF(X18="Reviewed - Format",90%,IF(X18="Done",100%,""))))))) -> 0
A19: 18 | B19: 5.2.4.1. | C19: Bilag 2 - Kravspecifikation | D19: Funktionelle krav | E19: Registrering, søgning og visning af sagsdata | F19: Sagsopslag og visning | G19: Sagsopslag og visning Brugerne skal kunne slå en sag op og se sagsbehandler, enhed, team, område samt ændre sagsdata ifm. sagens behandling. | I19: K - Konkurrencekrav | J19: =IF(I19="IK - Informationskrav","Answer",(IF(I19="K - Konkurrencekrav","Check",(IF(I19="MK - Mindstekrav","Verify",""))))) -> Check | K19: 1 | L19: 2 | M19: =Evalueringshieraki!$P$16 -> 0.48543689 | O19: Anton | R19: 1. Fully met | X19: Ready for review | Y19: =IF(X19="Not Started",0%,IF(X19="Read",1%,IF(X19="Started",50%,IF(X19="Ready for review",70%,IF(X19="Reviewed - Content",80%,IF(X19="Reviewed - Format",90%,IF(X19="Done",100%,""))))))) -> 0.7
A20: 19 | B20: 5.2.4.2. | C20: Bilag 2 - Kravspecifikation | D20: Funktionelle krav | E20: Registrering, søgning og visning af sagsdata | F20: Løbende registrering af sagsændringer | G20: Løbende registrering af sagsændringer Der skal løbende kunne registreres fx ændrede indsendelser, skift af team, enhed, sagsbehandler, sagsbehandling, om-registrering af sager ved evt. fejlvisitering/servicemålsager/lovliggørelse, ændringer af sagsstatus eks. dato for afgørelse. | I20: K - Konkurrencekrav | J20: =IF(I20="IK - Informationskrav","Answer",(IF(I20="K - Konkurrencekrav","Check",(IF(I20="MK - Mindstekrav","Verify",""))))) -> Check | K20: 1 | L20: 2 | M20: =Evalueringshieraki!$P$16 -> 0.48543689 | O20: Bjørn Henrik | R20: 1. Fully met | X20: Not Started | Y20: =IF(X20="Not Started",0%,IF(X20="Read",1%,IF(X20="Started",50%,IF(X20="Ready for review",70%,IF(X20="Reviewed - Content",80%,IF(X20="Reviewed - Format",90%,IF(X20="Done",100%,""))))))) -> 0
A21: 20 | B21: 5.2.4.3. | C21: Bilag 2 - Kravspecifikation | D21: Funktionelle krav | E21: Registrering, søgning og visning af sagsdata | F21: Søgning, sortering, filtrering og eksport | G21: Søgning, sortering, filtrering og eksport Sager skal kunne fremsøges på alle relevante sagsdata. Søgeresultaterne skal kunne sorteres, filtreres og eksporteres (fx til Excel) Det vægtes positivt, at Leverandøren i sin besvarelse demonstrerer, at Løsningen understøtter:  fritekst- og nøgleordssøgning  søgning på specifikke sætninger (frase søgning)  kombinerede søgekriterier (fx AND/OR-logik eller avancerede filtre)  sortering og filtrering af søgeresultater  eksport til gængse formater (fx Excel, CSV)  at sagsdata, herunder enhed og team, kan tilgås og ændres direkte fra søgeresultater eller sagsopslag uden unødige mellemtrin | I21: IK - Informationskrav | J21: =IF(I21="IK - Informationskrav","Answer",(IF(I21="K - Konkurrencekrav","Check",(IF(I21="MK - Mindstekrav","Verify",""))))) -> Answer | K21: 1 | L21: 2 | M21: =Evalueringshieraki!$P$16 -> 0.48543689 | O21: Anita | W21: Bilag 2 - 5.2.4.3 - Søgning, sortering, filtrering og eksport.docx | X21: Not Started | Y21: =IF(X21="Not Started",0%,IF(X21="Read",1%,IF(X21="Started",50%,IF(X21="Ready for review",70%,IF(X21="Reviewed - Content",80%,IF(X21="Reviewed - Format",90%,IF(X21="Done",100%,""))))))) -> 0
A22: 21 | B22: 5.2.5.1. | C22: Bilag 2 - Kravspecifikation | D22: Funktionelle krav | E22: Integration til GIS løsning | F22: GIS visning af sager | G22: GIS visning af sager Brugeren kan gennem løsningen tilgå en visning af Kundens GIS-løsning, med mulighed for præ-definerede filtre/overlays så man kan se relevant info fra Kundens GIS-løsning. Kundens GIS-løsning, vil automatisk have byggesagsejendommen i fokus for sagsbehandleren, så mest data er tilgængeligt, hurtigst muligt. Det vægtes positivt, at Leverandøren i sin besvarelse demonstrerer, at løsningen understøtter: • at GIS-visningen åbnes direkte i Løsningen uden unødige mellemtrin eller skift af applikation (fx dybe links fra løsning til GIS på relevant adresse/matrikel) • at præ-definerede filtre og overlays kan tilpasses af Kunden uden behov for systemudvikling • at GIS-visningen automatisk centrerer sig om den relevante ejendom med mest muligt data tilgængeligt fra første visning • at GIS-visningen giver mulighed for at identificere eventuelle konflikter og relevante oplysninger om ejendommen på tværs af lag og filtre • At visningen kan gemmes på sagen som dokumentation | I22: IK - Informationskrav | J22: =IF(I22="IK - Informationskrav","Answer",(IF(I22="K - Konkurrencekrav","Check",(IF(I22="MK - Mindstekrav","Verify",""))))) -> Answer | K22: 1 | L22: 2 | M22: =Evalueringshieraki!$P$16 -> 0.48543689 | O22: Husein | W22: Bilag 2 - 5.2.5.1 - GIS visning af sager.docx | X22: Not Started | Y22: =IF(X22="Not Started",0%,IF(X22="Read",1%,IF(X22="Started",50%,IF(X22="Ready for review",70%,IF(X22="Reviewed - Content",80%,IF(X22="Reviewed - Format",90%,IF(X22="Done",100%,""))))))) -> 0
A23: 22 | B23: B2-01 | C23: Bilag 2 - Kravspecifikation | D23: Funktionelle krav | E23: Sagsbehandling af byggesager og anmeldelser | F23: Sagsbehandling af byggesager og anmeldelser | G23: Løsningen skal understøtte modtagelse, oprettelse og sagsbehandling af de sagstyper, der er beskrevet i kravspecifikationens begrebsliste og faglige ramme, herunder byggetilladelser, anmeldelser, ibrugtagningstilladelser, lovliggørelsessager og klagesager. Som fagsystem skal løsningen understøtte udarbejdelse af myndighedsdokumentation og kommunikation med ansøgere mfl. Samtidig skal løsningen kunne give overblik over både de enkelte sager og deres status samt understøtte visitation, prioritering og opfølgning på sager og sagstyper. | I23: MK - Minimumskrav | J23: =IF(I23="IK - Informationskrav","Answer",(IF(I23="K - Konkurrencekrav","Check",(IF(I23="MK - Minimumskrav","Verify",""))))) -> Verify | O23: Bjørn Henrik | S23: Konfigurasjon | X23: Not Started | Y23: =IF(X23="Not Started",0%,IF(X23="Read",1%,IF(X23="Started",50%,IF(X23="Ready for review",70%,IF(X23="Reviewed - Content",80%,IF(X23="Reviewed - Format",90%,IF(X23="Done",100%,""))))))) -> 0
A24: 23 | B24: 5.2.6.1. | C24: Bilag 2 - Kravspecifikation | D24: Funktionelle krav | E24: Sagsbehandling af byggesager og anmeldelser | F24: - | G24: Brugeren kan tilgå en liste af sager på samme ejendom – brugeren kan vælge mellem at se sager på hele ejendommen, den konkrete adresse, BFE eller matrikel. | I24: K - Konkurrencekrav | J24: =IF(I24="IK - Informationskrav","Answer",(IF(I24="K - Konkurrencekrav","Check",(IF(I24="MK - Minimumskrav","Verify",""))))) -> Check | K24: 1 | L24: 2 | M24: =Evalueringshieraki!$P$16 -> 0.48543689 | O24: Husein | X24: Not Started | Y24: =IF(X24="Not Started",0%,IF(X24="Read",1%,IF(X24="Started",50%,IF(X24="Ready for review",70%,IF(X24="Reviewed - Content",80%,IF(X24="Reviewed - Format",90%,IF(X24="Done",100%,""))))))) -> 0
A25: 24 | B25: 5.2.6.2. | C25: Bilag 2 - Kravspecifikation | D25: Funktionelle krav | E25: Sagsbehandling af byggesager og anmeldelser | F25: - | G25: Brugeren kan hente/oprette relevante arbejdsdokumenter. Brugeren gemmer sit arbejde direkte i fagsystemet. Arbejdsdokumenter kan omfatte, men er ikke begrænset til: • Mangelbreve • Byggetilladelser • Ibrugtagningstilladelser • Afslag eller afvisninger på byggesager • Påbud/varsel om påbud • Høringer • Orienteringsbreve • Brev om forhåndsdialog • Lovliggørelser • Dispensationer • Mails | I25: K - Konkurrencekrav | J25: =IF(I25="IK - Informationskrav","Answer",(IF(I25="K - Konkurrencekrav","Check",(IF(I25="MK - Mindstekrav","Verify",""))))) -> Check | K25: 1 | L25: 2 | M25: =Evalueringshieraki!$P$16 -> 0.48543689 | O25: Anton | R25: 1. Fully met | X25: Ready for review | Y25: =IF(X25="Not Started",0%,IF(X25="Read",1%,IF(X25="Started",50%,IF(X25="Ready for review",70%,IF(X25="Reviewed - Content",80%,IF(X25="Reviewed - Format",90%,IF(X25="Done",100%,""))))))) -> 0.7
A26: 25 | B26: 5.2.6.3. | C26: Bilag 2 - Kravspecifikation | D26: Funktionelle krav | E26: Sagsbehandling af byggesager og anmeldelser | F26: Sags/journalnoter | G26: Sags/journalnoter Leverandøren bedes beskrive hvordan sagsbehandlere med adgang til en given sag kan notere relevante bemærkninger på sagen – f.eks. telefonnotater. Det vægtes positivt hvis: - Det noteres et centralt sted på sagen, som alle med relevant adgang kan tilgå. - Bemærkninger kan tidsstemples og knyttes til den bruger, som har oprettet dem. - Det er muligt at skelne mellem interne bemærkninger og bemærkninger der må deles med eksterne parter. - Tidligere bemærkninger forbliver synlige og kan ikke slettes eller redigeres af andre end den oprindelige ophavsmand eller administrator. - Brugeren kan notificeres, tagges eller på anden måde gøres opmærksom på en bemærkning der er relevant for vedkommende. - Disse noter kan udskrives og gemmes samlet om ønsket | I26: IK - Informationskrav | J26: =IF(I26="IK - Informationskrav","Answer",(IF(I26="K - Konkurrencekrav","Check",(IF(I26="MK - Mindstekrav","Verify",""))))) -> Answer | K26: 1 | L26: 2 | M26: =Evalueringshieraki!$P$16 -> 0.48543689 | O26: Bjørn Henrik | S26: Is this just Notes and note summaries? | W26: Bilag 2 - 5.2.6.3 - Sags-journalnoter.docx | X26: Not Started | Y26: =IF(X26="Not Started",0%,IF(X26="Read",1%,IF(X26="Started",50%,IF(X26="Ready for review",70%,IF(X26="Reviewed - Content",80%,IF(X26="Reviewed - Format",90%,IF(X26="Done",100%,""))))))) -> 0
A27: 26 | B27: 5.2.6.4. | C27: Bilag 2 - Kravspecifikation | D27: Funktionelle krav | E27: Sagsbehandling af byggesager og anmeldelser | F27: Overblik på sagen | G27: Overblik på sagen Leverandøren bedes beskrive hvordan brugeren, efter at have åbnet en given sag, kan få et overblik over sagens indhold og de seneste hændelser på sagen. Det vægtes positivt hvis: - Brugeren fra sagens forside, let kan tilgå yderligere oplysninger, - Overblikket er overskueligt - Det er ukompliceret at identificere seneste hændelser på sagen. | I27: IK - Informationskrav | J27: =IF(I27="IK - Informationskrav","Answer",(IF(I27="K - Konkurrencekrav","Check",(IF(I27="MK - Mindstekrav","Verify",""))))) -> Answer | K27: 1 | L27: 2 | M27: =Evalueringshieraki!$P$16 -> 0.48543689 | O27: Bjørn Henrik | W27: Bilag 2 - 5.2.6.4 - Overblik på sagen.docx | X27: Not Started | Y27: =IF(X27="Not Started",0%,IF(X27="Read",1%,IF(X27="Started",50%,IF(X27="Ready for review",70%,IF(X27="Reviewed - Content",80%,IF(X27="Reviewed - Format",90%,IF(X27="Done",100%,""))))))) -> 0
A28: 27 | B28: 5.2.6.5. | C28: Bilag 2 - Kravspecifikation | D28: Funktionelle krav | E28: Sagsbehandling af byggesager og anmeldelser | F28: Ansøgninger og anmeldelser på sagen | G28: Ansøgninger og anmeldelser på sagen Brugeren skal ud fra sagens visning kunne se hvilke aktive og afsluttede ansøgninger og anmeldelser, der er knyttet til den pågældende sag. Løsningen skal sikre at væsentlige datoer for sagsbehandlingen kan både søges, vises og indgå i rapporter. Det gælder fx dato for modtagelse, for fyldestgørende, for afslag, for byggetilladelse mm. Det vægtes positivt hvis: - Tilknyttede ansøgninger og anmeldelser fremgår samlet og overskueligt direkte fra sagens visning, med tydelig angivelse af status for hver enkelt. - Brugeren kan tilpasse hvilke datofelter der vises i sagens overblik, så de mest relevante datoer fremhæves for den konkrete sagstype. - Væsentlige datoer kan danne grundlag for automatiske påmindelser eller advarsler, fx ved overskridelse af servicemål eller frister. - Rapporter med datooplysninger kan eksporteres i et format der understøtter videre bearbejdning, fx Excel eller CSV. | I28: IK - Informationskrav | J28: =IF(I28="IK - Informationskrav","Answer",(IF(I28="K - Konkurrencekrav","Check",(IF(I28="MK - Mindstekrav","Verify",""))))) -> Answer | K28: 1 | L28: 2 | M28: =Evalueringshieraki!$P$16 -> 0.48543689 | O28: Linn | W28: Bilag 2 - 5.2.6.5 - Ansøgninger og anmeldelser på sagen.docx | X28: Not Started | Y28: =IF(X28="Not Started",0%,IF(X28="Read",1%,IF(X28="Started",50%,IF(X28="Ready for review",70%,IF(X28="Reviewed - Content",80%,IF(X28="Reviewed - Format",90%,IF(X28="Done",100%,""))))))) -> 0
A29: 28 | B29: 5.2.6.6. | C29: Bilag 2 - Kravspecifikation | D29: Funktionelle krav | E29: Sagsbehandling af byggesager og anmeldelser | F29: Overblik på sagsdokumenter | G29: Overblik på sagsdokumenter Leverandøren bedes beskrive hvordan brugeren kan emnemarkere, sortere og tilgå sagens dokumenter. Det vægtes positivt hvis: - Dokumenter kan tildeles brugerdefinerede kategorier eller dokumenttyper, som kan anvendes til filtrering og søgning på tværs af sagen. - Brugeren kan flytte, omdøbe og organisere dokumenter direkte i fagsystemet uden at forlade sagen. - Ændringer i dokumenthåndteringen logges, så det er muligt at se hvem der har foretaget ændringer og hvornår. | I29: IK - Informationskrav | J29: =IF(I29="IK - Informationskrav","Answer",(IF(I29="K - Konkurrencekrav","Check",(IF(I29="MK - Mindstekrav","Verify",""))))) -> Answer | K29: 1 | L29: 2 | M29: =Evalueringshieraki!$P$16 -> 0.48543689 | O29: Morten | W29: Bilag 2 - 5.2.6.6 - Overblik på sagsdokumenter.docx | X29: Not Started | Y29: =IF(X29="Not Started",0%,IF(X29="Read",1%,IF(X29="Started",50%,IF(X29="Ready for review",70%,IF(X29="Reviewed - Content",80%,IF(X29="Reviewed - Format",90%,IF(X29="Done",100%,""))))))) -> 0
A30: 29 | B30: 5.2.7.1. | C30: Bilag 2 - Kravspecifikation | D30: Funktionelle krav | E30: Styring af sagsportefølje | F30: Sagsoverblik og adviseringer | G30: Sagsoverblik og adviseringer En sagsbehandler eller et team kan se et overblik over sager som de har ansvaret for, i løsningen. Dette overblik giver information om adviseringer – fx overskredne frister, indkommende dokumentation eller lign. Overblikket viser hvor mange sager af forskellige typer som en sagsbehandler eller et team, har ansvar for. Bruger kan tilgå enkeltsager via overblikket. | I30: K - Konkurrencekrav | J30: =IF(I30="IK - Informationskrav","Answer",(IF(I30="K - Konkurrencekrav","Check",(IF(I30="MK - Mindstekrav","Verify",""))))) -> Check | K30: 1 | L30: 2 | M30: =Evalueringshieraki!$P$16 -> 0.48543689 | O30: Morten | S30: The dashboard is supposed to give notifications? Does it show new documents are created from the desktop? | X30: Not Started | Y30: =IF(X30="Not Started",0%,IF(X30="Read",1%,IF(X30="Started",50%,IF(X30="Ready for review",70%,IF(X30="Reviewed - Content",80%,IF(X30="Reviewed - Format",90%,IF(X30="Done",100%,""))))))) -> 0
A31: 30 | B31: 5.2.7.2. | C31: Bilag 2 - Kravspecifikation | D31: Funktionelle krav | E31: Styring af sagsportefølje | F31: Tilpasset overbliksvisning og sortering | G31: Tilpasset overbliksvisning og sortering Leverandøren bedes give en udtømmende beskrivelse af, hvordan Løsningen understøtter tilpasning og sortering af overbliksvisningen, herunder: Brugere kan opsætte sin egen visning af dette overblik så de fx ét sted kun ser de sager, som er relevante nu og undgår at se sager, som afventer andre – fx ansøger, kollega og lign. De afventende sager skal kunne ses for sig, i samme overbliksvisning. Opsætning af overbliksvisning skal kunne tilpasses individuelt, både til enkelte brugere og til teams med prædefineret opsætning. Bruger kan sortere på forskellige parametre, fx emner, dato, sagsfase, tags, prioriteringer. Systemet skal give mulighed for at skifte mellem forskellige overbliksvisninger. Det vægtes positivt, at Leverandøren i sin besvarelse demonstrerer, at Løsningen understøtter:  at brugere kan oprette og gemme flere personlige overbliksvisninger og frit skifte imellem dem  at teams kan dele og anvende fælles prædefineret overbliksvisninger  at afventende sager præsenteres tydeligt adskilt fra aktive sager i samme overbliksvisning  at sortering kan foretages på tværs af flere parametre samtidigt (fx sagsfase og dato kombineret)  at adviseringer om overskredne frister og indkommende dokumentation fremhæves tydeligt i overblikket  at overbliksvisningen kan tilpasses uden behov for systemudvikling | I31: IK - Informationskrav | J31: =IF(I31="IK - Informationskrav","Answer",(IF(I31="K - Konkurrencekrav","Check",(IF(I31="MK - Mindstekrav","Verify",""))))) -> Answer | K31: 1 | L31: 2 | M31: =Evalueringshieraki!$P$16 -> 0.48543689 | O31: Morten | W31: Bilag 2 - 5.2.7.2 - Tilpasset overbliksvisning og sortering.docx | X31: Not Started | Y31: =IF(X31="Not Started",0%,IF(X31="Read",1%,IF(X31="Started",50%,IF(X31="Ready for review",70%,IF(X31="Reviewed - Content",80%,IF(X31="Reviewed - Format",90%,IF(X31="Done",100%,""))))))) -> 0
A32: 31 | B32: 5.2.8.1. | C32: Bilag 2 - Kravspecifikation | D32: Funktionelle krav | E32: Understøttelse af alle sagstyper | F32: - | G32: Sager skal kunne inddeles i forskellige typer i relation til typer af sager, ejendomme og byggeri, således at sagskategorien svarer til den type af byggeri eller sag, der er omfattet af sagen. | I32: K - Konkurrencekrav | J32: =IF(I32="IK - Informationskrav","Answer",(IF(I32="K - Konkurrencekrav","Check",(IF(I32="MK - Mindstekrav","Verify",""))))) -> Check | K32: 1 | L32: 2 | M32: =Evalueringshieraki!$P$16 -> 0.48543689 | O32: Bjørn Henrik | X32: Not Started | Y32: =IF(X32="Not Started",0%,IF(X32="Read",1%,IF(X32="Started",50%,IF(X32="Ready for review",70%,IF(X32="Reviewed - Content",80%,IF(X32="Reviewed - Format",90%,IF(X32="Done",100%,""))))))) -> 0
A33: 32 | B33: 5.2.8.2 | C33: Bilag 2 - Kravspecifikation | D33: Funktionelle krav | E33: Understøttelse af alle sagstyper | F33: - | G33: Sager skal kunne fordeles til enheder, teams og brugere baseret på type af sager. | I33: K - Konkurrencekrav | J33: =IF(I33="IK - Informationskrav","Answer",(IF(I33="K - Konkurrencekrav","Check",(IF(I33="MK - Mindstekrav","Verify",""))))) -> Check | K33: 1 | L33: 2 | M33: =Evalueringshieraki!$P$16 -> 0.48543689 | O33: Bjørn Henrik | X33: Not Started | Y33: =IF(X33="Not Started",0%,IF(X33="Read",1%,IF(X33="Started",50%,IF(X33="Ready for review",70%,IF(X33="Reviewed - Content",80%,IF(X33="Reviewed - Format",90%,IF(X33="Done",100%,""))))))) -> 0
A34: 33 | B34: 5.2.8.3. | C34: Bilag 2 - Kravspecifikation | D34: Funktionelle krav | E34: Understøttelse af alle sagstyper | F34: - | G34: Brugere skal kunne fremsøge sager filtreret på typer af sager og få et overblik. Det skal fremgå af sagen, hvilken type den er. | I34: K - Konkurrencekrav | J34: =IF(I34="IK - Informationskrav","Answer",(IF(I34="K - Konkurrencekrav","Check",(IF(I34="MK - Mindstekrav","Verify",""))))) -> Check | K34: 1 | L34: 2 | M34: =Evalueringshieraki!$P$16 -> 0.48543689 | O34: Anton | R34: 1. Fully met | X34: Ready for review | Y34: =IF(X34="Not Started",0%,IF(X34="Read",1%,IF(X34="Started",50%,IF(X34="Ready for review",70%,IF(X34="Reviewed - Content",80%,IF(X34="Reviewed - Format",90%,IF(X34="Done",100%,""))))))) -> 0.7
A35: 34 | B35: 5.2.8.4. | C35: Bilag 2 - Kravspecifikation | D35: Funktionelle krav | E35: Understøttelse af alle sagstyper | F35: Sagsstatus | G35: sagsstatus Brugeren kan ud fra sagsvisningen tydeligt se sagens status, dvs. hvor langt en sag er nået i processen, samt hvor initiativpligten ligger og hvem der er ansvarlig for sagen. Ligesom manglende data eller udestående procestrin bør fremgå af sagens statusmarkeringer. Det vægtes positivt hvis: - Sagens status vises visuelt og intuitivt, fx via en proceslinje eller statusindikator, der tydeligt markerer gennemførte, igangværende og udestående faser. - Initiativpligten fremgår eksplicit af sagens visning, så det er klart om bolden ligger hos ansøger, sagsbehandler eller en tredjepart. - Brugeren adviseres automatisk når manglende data eller udestående procestrin blokerer for videre sagsbehandling, fx via en synlig advarsel eller notifikation direkte på sagen. - Det er muligt at konfigurere hvilke felter og procestrin der er obligatoriske for den enkelte sagstype, så statusmarkeringerne afspejler kravene til den konkrete sag. | I35: IK - Informationskrav | J35: =IF(I35="IK - Informationskrav","Answer",(IF(I35="K - Konkurrencekrav","Check",(IF(I35="MK - Mindstekrav","Verify",""))))) -> Answer | K35: 1 | L35: 2 | M35: =Evalueringshieraki!$P$16 -> 0.48543689 | O35: Bjørn Henrik | W35: Bilag 2 - 5.2.8.4 - Sagsstatus.docx | X35: Not Started | Y35: =IF(X35="Not Started",0%,IF(X35="Read",1%,IF(X35="Started",50%,IF(X35="Ready for review",70%,IF(X35="Reviewed - Content",80%,IF(X35="Reviewed - Format",90%,IF(X35="Done",100%,""))))))) -> 0
A36: 35 | B36: 5.2.8.5. | C36: Bilag 2 - Kravspecifikation | D36: Funktionelle krav | E36: Understøttelse af alle sagstyper | F36: Håndtering af modtaget information | G36: Håndtering af modtaget information Løsningen skal kunne håndtere indkomne dokumentationer/data efter sagens status (hvor i processen sagen er). Det vægtes positivt hvis: - Løsningen automatisk kategoriserer eller placerer indkomne dokumenter og data i relation til den fase af processen, hvori de er modtaget. - Brugeren adviseres når der indkommer dokumentation på en sag. | I36: IK - Informationskrav | J36: =IF(I36="IK - Informationskrav","Answer",(IF(I36="K - Konkurrencekrav","Check",(IF(I36="MK - Mindstekrav","Verify",""))))) -> Answer | K36: 1 | L36: 2 | M36: =Evalueringshieraki!$P$16 -> 0.48543689 | O36: Bjørn Henrik | W36: Bilag 2 - 5.2.8.5 - Håndtering af modtaget information.docx | X36: Not Started | Y36: =IF(X36="Not Started",0%,IF(X36="Read",1%,IF(X36="Started",50%,IF(X36="Ready for review",70%,IF(X36="Reviewed - Content",80%,IF(X36="Reviewed - Format",90%,IF(X36="Done",100%,""))))))) -> 0
A37: 36 | B37: 5.2.8.6. | C37: Bilag 2 - Kravspecifikation | D37: Funktionelle krav | E37: Understøttelse af alle sagstyper | F37: - | G37: Overblik over alle afgørelser på sagen. | I37: K - Konkurrencekrav | J37: =IF(I37="IK - Informationskrav","Answer",(IF(I37="K - Konkurrencekrav","Check",(IF(I37="MK - Mindstekrav","Verify",""))))) -> Check | K37: 1 | L37: 2 | M37: =Evalueringshieraki!$P$16 -> 0.48543689 | O37: Bjørn Henrik | R37: 1. Fully met | S37: We should ask a question about this - IF we see any issues with it - otherwise we let it stand. | X37: Not Started | Y37: =IF(X37="Not Started",0%,IF(X37="Read",1%,IF(X37="Started",50%,IF(X37="Ready for review",70%,IF(X37="Reviewed - Content",80%,IF(X37="Reviewed - Format",90%,IF(X37="Done",100%,""))))))) -> 0
A38: 37 | B38: 5.2.8.7. | C38: Bilag 2 - Kravspecifikation | D38: Funktionelle krav | E38: Understøttelse af alle sagstyper | F38: - | G38: Man skal ikke kunne arbejde videre på en afsluttet sag. Det skal dog være muligt at genåbne en lukket sag (for brugere med særlig rettighed). | I38: K - Konkurrencekrav | J38: =IF(I38="IK - Informationskrav","Answer",(IF(I38="K - Konkurrencekrav","Check",(IF(I38="MK - Mindstekrav","Verify",""))))) -> Check | K38: 1 | L38: 2 | M38: =Evalueringshieraki!$P$16 -> 0.48543689 | O38: Anton | R38: 1. Fully met | X38: Ready for review | Y38: =IF(X38="Not Started",0%,IF(X38="Read",1%,IF(X38="Started",50%,IF(X38="Ready for review",70%,IF(X38="Reviewed - Content",80%,IF(X38="Reviewed - Format",90%,IF(X38="Done",100%,""))))))) -> 0.7
A39: 38 | B39: 5.2.8.8. | C39: Bilag 2 - Kravspecifikation | D39: Funktionelle krav | E39: Understøttelse af alle sagstyper | F39: Kommunikation | G39: Kommunikation Brugeren kan via systemet gennemføre dialog og kommunikation med ansøgere og interessenter gennem Digital Post, landsdækkende ansøgningsportal (BOM) og e-mail eller tilsvarende kommunikationsplatform. Det vægtes positivt hvis: - Kommunikation via Digital Post, BOM og e-mail kan initieres og håndteres samlet fra ét sted i fagsystemet, uden at brugeren skal skifte mellem separate platforme. - Kommunikation med ansøgere og interessenter, foretaget gennem Systemets kommunikationskanaler, automatisk journaliseres og knyttes til den relevante sag. - Brugeren kan anvende foruddefinerede skabeloner til standardiseret kommunikation, som kan tilpasses den konkrete sag og den relevante modtager. - Man skal kunne se, hvis modtagelse/afsendelse fejler | I39: IK - Informationskrav | J39: =IF(I39="IK - Informationskrav","Answer",(IF(I39="K - Konkurrencekrav","Check",(IF(I39="MK - Mindstekrav","Verify",""))))) -> Answer | K39: 1 | L39: 2 | M39: =Evalueringshieraki!$P$16 -> 0.48543689 | O39: Morten | S39: PnB tar ansvaret for BOM, resten er standard funksjonalitet? | W39: Bilag 2 - 5.2.8.8 - Kommunikation.docx | X39: Not Started | Y39: =IF(X39="Not Started",0%,IF(X39="Read",1%,IF(X39="Started",50%,IF(X39="Ready for review",70%,IF(X39="Reviewed - Content",80%,IF(X39="Reviewed - Format",90%,IF(X39="Done",100%,""))))))) -> 0
A40: 39 | B40: 5.2.8.9. | C40: Bilag 2 - Kravspecifikation | D40: Funktionelle krav | E40: Understøttelse af alle sagstyper | F40: - | G40: Systemet kan opdatere sagsstatus for byggesager gennem kommunikation via landsdækkende ansøgningsportal Byg og Miljø (BOM). | I40: K - Konkurrencekrav | J40: =IF(I40="IK - Informationskrav","Answer",(IF(I40="K - Konkurrencekrav","Check",(IF(I40="MK - Mindstekrav","Verify",""))))) -> Check | K40: 1 | L40: 2 | M40: =Evalueringshieraki!$P$16 -> 0.48543689 | O40: Arve | R40: 1. Fully met | S40: BOM integrasjon | X40: Not Started | Y40: =IF(X40="Not Started",0%,IF(X40="Read",1%,IF(X40="Started",50%,IF(X40="Ready for review",70%,IF(X40="Reviewed - Content",80%,IF(X40="Reviewed - Format",90%,IF(X40="Done",100%,""))))))) -> 0
...

Sheet IK-krav
A1: # | B1: ReqID | C1: Document | D1: Section (Headline) | E1: Subsection | F1: Requirement title | G1: Requirement | H1: Besvarelsesvejledning | I1: Requirement type | J1: Action | K1: Round #1 | L1: Responsible | M1: Reviewer | N1: Module | O1: Can we meet the requirement? | P1: Comment | Q1: Commitment needed? | R1: Risk Element? | S1: Cost Driver | T1: Link to answer document | U1: Status (phase) | V1: Status (%)
A2: 1 | B2: 4.1.1. | C2: Bilag 2 - Kravspecifikation | D2: Tidsplan (15%) | E2: Implementering og tidsplan | F2: Implementeringsplan | G2: Implementeringsplan Leverandøren skal beskrive sin samlede plan for implementering af Løsningen hos Kunden. Beskrivelsen skal omfatte punkterne i Bilag 11 Dokumentations, pkt. 7: Det vægtes positivt, at:  Leverandøren demonstrerer en klar forståelse for Kundens it-miljø og de tekniske forudsætninger, herunder relevante integrationer, snitflader, datamigrering og sikkerhedsmæssige forhold.  Tidsplanen afspejler Kundens organisation og implementeringens kompleksitet.  Leverandøren giver en sammenhængende og realistisk faseopdeling af implementeringsforløbet med klare milepæle og godkendelsespunkter, der sikrer, at Kunden kan godkende afslutning af en fase, før næste fase igangsættes.  Leverandøren tydeligt beskriver kendte risici og faldgruber i implementeringsforløbet, samt konkrete mitigerende tiltag.  At tidsplanen tager højde for, at Ordregiver har en løbende drift der skal varetages og perioder med begrænsede ressourcer | H2: Informationskravet besvares ved at Leverandøren vedhæfter eget bilag og udfylder tabel 5.4. (Detaljeret tidsplan) i Bilag 1 - Implementering | I2: IK - Informationskrav | J2: Answer | L2: Cristina
A3: 2 | B3: 4.2.1. | C3: Bilag 2 - Kravspecifikation | D3: Tidsplan (15%) | E3: Tidsplan for optioner | F3: Tidsplan for optioner | G3: Tidsplan for optioner Leverandøren bedes redegøre for hvornår optionerne, jf. punkt 5.4. (5.4.1. & 5.4.2.) i nærværende bilag, kan forventes færdigleveret efter Kunden har kaldt optioner. Leverandøren skal indregne alle relevante faktorer, såsom udvikling af integrationen, men også forhold hos Kunden som Leverandøren er bekendt med ud fra nærværende materiale samt tilhørende bilag. Det vægter positivt at - optionen tilbydes til levering så tæt på Overtagelsesdagen, som muligt. - tidligste dato for Kundens kald af optionen er så tæt på Kontraktindgåelsesdatoen, som muligt. | H3: Informationskravet besvares ved at Leverandøren vedhæfter eget bilag. | I3: IK - Informationskrav | J3: Answer | L3: Cristina
A4: 3 | B4: 5.1.1.1. | C4: Bilag 2 - Kravspecifikation | D4: Generelle krav | E4: Test og prøver | F4: Prøveplan | G4: Prøveplan Leverandøren skal beskrive teststrategien og redegøre for hvorledes aktiviteterne bedst påviser, at kravene i Bilag 2 (Kravspecifikation) efterleves. Det vægtes positivt, at:  Leverandøren beskriver teststrategien på en måde, så den tydelig beskriver, hvilken teststrategi Leverandøren anvender for at sikre, at Løsningen lever op til Kundens krav  Leverandøren beskriver eksempler på prøveplaner og testrapport med angivelse af ansvarsfordeling, testprincipper, metoder og værktøjer mm.  Leverandøren beskriver hvordan og i hvilken grad testcases udledes af Kundens krav  Hvordan dokumenteres og sikres kvalitet og stabilitet under test og prøver, f.eks. ved brug af dedikerede testværktøjer såsom Azure DevOps el.lign. | H4: Informationskravet besvares ved at Leverandøren vedhæfter eget bilag. | I4: IK - Informationskrav | J4: Answer | L4: Cristina
A5: 4 | B5: 5.1.2.1. | C5: Bilag 2 - Kravspecifikation | D5: Generelle krav | E5: Uddannelse | F5: Uddannelse | G5: Uddannelse Leverandøren skal levere en uddannelsesplan, der medfører at de forskellige typer af Brugere er i stand til at anvende Systemet ved idriftsættelse. Besvarelsen bør tage udgangspunkt i nærværende krav samt Bilag 1 (Implementering) pkt. 7 og Bilag 11 (Dokumentation) pkt. 7. Leverandøren skal i besvarelsen redegøre for deres undervisningstilbud i Løsningen, herunder de(n) tilknyttede instruktørers undervisningserfaring. Det vægtes positivt, at: - at der for de enkelte kurser er klare, konkrete og realistiske læringsmål - at det viser organiseringen af den tilbudte undervisning - at uddannelsen i videst muligt omfang tager afsæt i de forskellige Brugeres faglige profil og relevante arbejdsgange - at kurserne i videst muligt omfang behandler Kundens centrale arbejdsgange - at instruktører er erfarne i at undervise og kender målgruppens hverdag | H5: Informationskravet besvares i Leverandørens eget bilag. | I5: IK - Informationskrav | J5: Answer | L5: Anton | M5: Tony, Cristian
A6: 5 | B6: 5.1.3.1. | C6: Bilag 2 - Kravspecifikation | D6: Generelle krav | E6: Data migrering og konvertering | F6: Migreringsplan | G6: Migreringsplan Leverandøren skal levere en migreringsplan og bedes redegøre for hvordan migrering fra Kundens eksisterende system til Systemet vil forløbe med udgangspunkt i kravene i Bilag 1 Implementering, pkt. 6. Migreringsplanens udformning og indhold skal følge Bilag 11 (Dokumentation) pkt. 7. Det vægter positivt at: - dataintegritet af migreringen valideres løbende, f.eks. gennem checksum, tests og overvågning. - data håndteres sikkert, f.eks. ved kryptering. - data migreres og konverteres så automatisk som muligt. - der er indtænkt processer for håndtering af fejl - datamigrering påvirker Brugerens arbejde mindst muligt - besvarelsen indeholder flere konkrete eksempler og detaljer vedr. migreringsaktiviteter. | H6: Informationskravet besvares i Leverandørens eget bilag. | I6: IK - Informationskrav | J6: Answer | L6: Kaare
A7: 6 | B7: 5.2.1.1. | C7: Bilag 2 - Kravspecifikation | D7: Funktionelle krav | E7: Journalisering, dokumenthåndtering og sagsoverblik | F7: Opmærkning af sager og dokumenter | G7: Opmærkning af sager og dokumenter Både sager og dokumenter skal kunne opmærkes, struktureres eller tildeles ”tags” på baggrund af emne, type, kategori m.m. som gør det lettere at søge, sortere og få overblik over data. Løsningen skal give mulighed for sortering på fx indsendelser, dato, emne, teknisk kapitel (fra BOM), fase (fra BOM, bl.a. 'ansøgning', 'under arbejde', 'efter endt arbejde' osv.). Det vægtes positivt, at Leverandøren i sin besvarelse demonstrerer, at Løsningen understøtter:  at data og dokumentation automatisk inddeles i en logisk og overskuelig struktur på sagen  at sagsbehandlere fleksibelt kan tilpasse strukturen til den enkelte sag eller sagstype  at "tag"-funktionen giver mulighed for at tagge på tværs af evt. dokumentstruktur og dokumenttyper  at sortering kan foretages på flere parametre samtidigt (fx fase og dato kombineret)  at sortering og inddeling er konsistent på tværs af sager og sagstyper, så der sikres ensartethed i sagsbehandlingen  at nye sorteringsparametre kan tilføjes uden behov for systemudvikling  At man hurtigt kan se, hvad der er sagsbehandlet og hvad der udestår. | I7: IK - Informationskrav | J7: Answer | L7: PnB
A8: 7 | B8: 5.2.1.2. | C8: Bilag 2 - Kravspecifikation | D8: Funktionelle krav | E8: Journalisering, dokumenthåndtering og sagsoverblik | F8: Konfliktløsning | G8: Konfliktløsning Løsningen skal kunne initiere/kalde en konfliktsøgning der foretages af andet system. Det være sig GIS, en robot eller AI løsning. Initieringen kan være på baggrund af en matrikel, BFE-nr., adresse eller lignende (som altså kan medsendes i kaldet til det eksterne system) Det vægtes positivt, at Leverandøren i sin besvarelse demonstrerer, at Løsningen understøtter:  at konfliktsøgningen kan sættes til at køre automatisk ved oprettelse af nye sager  at sagsbehandler adviseres tydeligt, hvis der identificeres konflikter  at det angives hvis der er adressebeskyttelse eller fortrolighed  at konfliktsøgningen kan gemmes som et dokument på sagen, meget gerne automatisk | I8: IK - Informationskrav | J8: Answer | L8: PnB
A9: 8 | B9: 5.2.1.6. | C9: Bilag 2 - Kravspecifikation | D9: Funktionelle krav | E9: Journalisering, dokumenthåndtering og sagsoverblik | F9: Understøttelse af Elektronisk Sags- og Dokumenthåndtering | G9: Understøttelse af Elektronisk Sags- og Dokumenthåndtering Leverandøren bedes redegøre for i hvilket omfang Løsningen kan understøtte Brugeren i at løfte journaliseringspligt, jf. offentliglovens § 15. Det vægter positivt at: - Kunden kan opsætte regler for hvem der kan redigere, slette fejloprettede sager eller genåbne afsluttede sager. - Løsningen understøtter automatisk journalisering - Dokumenter modtaget på sagerne journaliseres. - Notater nemt kan journaliseres af Brugeren. - Kommunikation der initieres eller modtages af systemet automatisk journaliseres på sagen. - Journaliserede elementer er tydeligt dateret. - Journaliseret indhold er opmærket så det er tydeligt hvad indholdet er. - Mulighed for KLE-opmærkning af sager | I9: IK - Informationskrav | J9: Answer
A10: 9 | B10: 5.2.2.1. | C10: Bilag 2 - Kravspecifikation | D10: Funktionelle krav | E10: Hentning og opdatering af ejendomsdata | F10: Ejendomsdata | G10: IK Ejendomsdata Løsningen skal hente og anvende nedenstående ejendomsdata fra Datafordeleren:  Adresser inklusive vejnavn, husnummer, postnummer og postdistrikt.  Bygningsnummer.  Bestemt fast ejendomsnummer (herefter ”BFE”) for grund, ejerlejlighed og Bygning på fremmed grund (herefter ”BPFG”)  Matrikelnummer og ejerlav.  Ejerlejlighedsnummer.  Bygningens anvendelseskode (fx parcelhus, erhverv, institution).  Bygningens opførelses år.  Bebygget areal og samlet bygningsareal.  Antal bolig- og erhvervsenheder.  Energikilde og varmeinstallation.  Ejerforhold fra Ejerfortegnelsen (herefter ”EJF”), herunder oplysninger om hvem der råder over fast ejendom.  Ejendomsbeliggenhedsregistret (herefter ”EBR”), herunder referencer mellem ejendomme og adresser/beliggenhedsbetegnelser. Løsningens skal sikre opdatering af ejendomsdata på alle verserende sager mindst én gang i døgnet, og både historiske og aktuelle data skal vises på sagerne. Ejendomsdata skal være søgbare - både enkeltvis og i kombination med øvrige data. Det vægtes positivt at  at sagsbehandlere kan søge på alle ejendomsdata og finde både aktuelle og historiske sager, enkeltvis eller i kombination med øvrige søgekriterier, herunder ved brug af AND/OR-logik eller avancerede filtre  at ejendomsdata kan danne udgangspunkt for filtrering, lister og sortering af fremsøgte sager, samt at søgeresultater kan eksporteres til gængse formater (fx Excel, CSV)  at ejendomsdata fremgår samlet og overskueligt på den enkelte sag  at sagsbehandlere, teams og enheder notificeres automatisk, når ejendomsdata ændres på verserende sager  at ændringer i ejendomsdata tilføjes sagen med angivelse af tidsstempel og brugeridentitet, uden at tidligere data slettes | I10: IK - Informationskrav | J10: Answer
A11: 10 | B11: 5.2.3.5. | C11: Bilag 2 - Kravspecifikation | D11: Funktionelle krav | E11: Registrering af ejere og interessenter | F11: Interessent roller | G11: Interessent roller Sagsbehandlerne har brug for at kunne notere hvilken rolle de enkelte interessenter har/har haft på sagen. Leverandøren bedes redegøre for hvordan rollerne til interessenter kan tildeles og evt. ændres. Det vægtes positivt at - kunden kan anvende faste kategorier - at interessenter kan fremsøges på baggrund af deres roller | I11: IK - Informationskrav | J11: Answer
A12: 11 | B12: 5.2.4.3. | C12: Bilag 2 - Kravspecifikation | D12: Funktionelle krav | E12: Registrering, søgning og visning af sagsdata | F12: Søgning, sortering, filtrering og eksport | G12: Søgning, sortering, filtrering og eksport Sager skal kunne fremsøges på alle relevante sagsdata. Søgeresultaterne skal kunne sorteres, filtreres og eksporteres (fx til Excel) Det vægtes positivt, at Leverandøren i sin besvarelse demonstrerer, at Løsningen understøtter:  fritekst- og nøgleordssøgning  søgning på specifikke sætninger (frase søgning)  kombinerede søgekriterier (fx AND/OR-logik eller avancerede filtre)  sortering og filtrering af søgeresultater  eksport til gængse formater (fx Excel, CSV)  at sagsdata, herunder enhed og team, kan tilgås og ændres direkte fra søgeresultater eller sagsopslag uden unødige mellemtrin | I12: IK - Informationskrav | J12: Answer
