Workbook

Sheet Production Plan
A1: # | B1: ReqID | C1: Document | D1: Section (Headline) | E1: Requirement title | F1: Requirement | G1: Requirement type | H1: Action | I1: Indgår i officiel krav-count? | J1: Vægt | K1: Round #1 | L1: Responsible | M1: Reviewer | N1: Module | O1: Can we meet the requirement? | P1: Comment | Q1: PFR-nr. | R1: Commitment needed? | S1: Risk Element? | T1: Cost Driver | U1: Link to answer document | V1: Status (phase) | W1: Status (%) | X1: AI — Generated | Y1: AI — Source | Z1: AI — Compliance | AA1: AI — Confidence | AB1: AI — Summary | AC1: AI — Gaps & clarifications | AD1: AI — Evidence | AE1: AI — Next action | AF1: AI — Reviewed by | AG1: AI — Review status | AH1: AI — Run ID
A2: 1 | B2: MK-1 | C2: Bilag 1.b | D2: Generelle krav | E2: Rigsarkivets afleveringsmodeller | F2: ESDH-løsningen skal understøtte Rigsarkivets gældende retningslinjer for anmeldelse og godkendelse af it-systemer fra statslige Myndigheder, jf. Cirkulære om anmeldelse og godkendelse af it-systemer på Retsinformation og gældende regler for generel aflevering af statslige it-systemer, jf. Bekendtgørelse om arkiveringsversioner på Retsinformation. | G2: Mindstekrav | H2: =IF(G2="Evalueringskrav","Answer",(IF(G2="Krav","Check",(IF(G2="Mindstekrav","Verify",""))))) -> Verify | I2: Ja | L2: Anton | O2: 1. Fully met | V2: Reviewed - Content | W2: =IF(V2="Not Started",0%,IF(V2="Started",50%,IF(V2="Ready for review",70%,IF(V2="Reviewed - Content",80%,IF(V2="Reviewed - Format",90%,IF(V2="Done",100%,"")))))) -> 0.8 | X2: 2026-07-07 | Y2: Cursor / tender-response (batch) | Z2: Met | AA2: Verified | AB2: Verify: Rigsarkivets afleveringsmodeller — vurderet opfyldt (tool: 1. Fully met). | AD2: docs/tender-reference/extracted/KK Tender tool.txt; docs/tender-reference/extracted/Nationalbanken/Bilag 3.i Leverandørens Løsningsbeskrivelse.txt; docs/product/RFP_Leverandørens_svar_utdrag.txt | AE2: Anton: Confirm verify-tekst; opdatér review status efter tjek. | AG2: Draft | AH2: uim-esdh-full-2026-07-07
A3: 2 | B3: MK-2 | C3: Bilag 1.b | D3: Generelle krav | E3: Sprog | F3: ESDH-løsningen skal understøtte dansk og engelsk. | G3: Mindstekrav | H3: =IF(G3="Evalueringskrav","Answer",(IF(G3="Krav","Check",(IF(G3="Mindstekrav","Verify",""))))) -> Verify | I3: Ja | L3: Anton | O3: 1. Fully met | V3: Reviewed - Content | W3: =IF(V3="Not Started",0%,IF(V3="Started",50%,IF(V3="Ready for review",70%,IF(V3="Reviewed - Content",80%,IF(V3="Reviewed - Format",90%,IF(V3="Done",100%,"")))))) -> 0.8 | X3: 2026-07-07 | Y3: Cursor / tender-response (batch) | Z3: Met | AA3: Verified | AB3: Verify: Sprog — vurderet opfyldt (tool: 1. Fully met). | AD3: docs/tender-reference/extracted/Nationalbanken/Bilag 3.i Leverandørens Løsningsbeskrivelse.txt; docs/tender-reference/extracted/HSØ/02.00-Tietoevry-SSA-L-Bilag 2-Leverandørens beskrivelse av Tjenesten.txt; docs/tender-reference/extracted/KK Tender tool.txt | AE3: Anton: Confirm verify-tekst; opdatér review status efter tjek. | AG3: Draft | AH3: uim-esdh-full-2026-07-07
A4: 3 | B4: MK-3 | C4: Bilag 1.b | D4: Generelle krav | E4: Datamodel | F4: ESDH-løsningen skal understøtte en Datamodel med en klar og tydelig beskrivelse af felterne i både frontend og backend. | G4: Mindstekrav | H4: =IF(G4="Evalueringskrav","Answer",(IF(G4="Krav","Check",(IF(G4="Mindstekrav","Verify",""))))) -> Verify | I4: Ja | L4: Anton | O4: 1. Fully met | V4: Reviewed - Content | W4: =IF(V4="Not Started",0%,IF(V4="Started",50%,IF(V4="Ready for review",70%,IF(V4="Reviewed - Content",80%,IF(V4="Reviewed - Format",90%,IF(V4="Done",100%,"")))))) -> 0.8 | X4: 2026-07-07 | Y4: Cursor / tender-response (batch) | Z4: Met | AA4: Verified | AB4: Verify: Datamodel — vurderet opfyldt (tool: 1. Fully met). | AD4: docs/tender-reference/extracted/KK Tender tool.txt; docs/product/RFP_Leverandørens_svar_utdrag.txt; docs/tender-reference/extracted/HSØ/02.00-Tietoevry-SSA-L-Bilag 2-Leverandørens beskrivelse av Tjenesten.txt | AE4: Anton: Confirm verify-tekst; opdatér review status efter tjek. | AG4: Draft | AH4: uim-esdh-full-2026-07-07
A5: 4 | B5: MK-4 | C5: Bilag 1.b | D5: Generelle krav | E5: GDPR – Ret til indsigt i egne personoplysninger | F5: ESDH-løsningen skal understøtte fremsøgning, sammenstilling og udlevering af personoplysninger om den registrerede i overensstemmelse med GDPR-artikel 15. ESDH-løsningen skal ligeledes understøtte behandling af anmodninger fremsat af en lovlig repræsentant for den registrerede, herunder forældremyndighed eller værgemål. Udleveringen skal kunne leveres i et almindelig læsbart format og skal kunne fremsendes til den registrerede via Digital Post, sikker e-mail og fjernprint. | G5: Mindstekrav | H5: =IF(G5="Evalueringskrav","Answer",(IF(G5="Krav","Check",(IF(G5="Mindstekrav","Verify",""))))) -> Verify | I5: Ja | L5: Anton | O5: 1. Fully met | V5: Reviewed - Content | W5: =IF(V5="Not Started",0%,IF(V5="Started",50%,IF(V5="Ready for review",70%,IF(V5="Reviewed - Content",80%,IF(V5="Reviewed - Format",90%,IF(V5="Done",100%,"")))))) -> 0.8 | X5: 2026-07-07 | Y5: Cursor / tender-response (batch) | Z5: Met | AA5: Verified | AB5: Verify: GDPR – Ret til indsigt i egne personoplysninger — vurderet opfyldt (tool: 1. Fully met). | AD5: docs/tender-reference/extracted/KK Tender tool.txt; docs/tender-reference/extracted/Nationalbanken/Bilag 3.i Leverandørens Løsningsbeskrivelse.txt; docs/tender-reference/extracted/Nationalbanken/Underbilag 6B - Testplan og Leverandørens prøveprincipper, metoder og -værktøjer (1).txt | AE5: Anton: Confirm verify-tekst; opdatér review status efter tjek. | AG5: Draft | AH5: uim-esdh-full-2026-07-07
A6: 5 | B6: MK-5 | C6: Bilag 1.b | D6: Generelle krav | E6: Anmodninger fra registrerede | F6: ESDH-løsningen skal understøtte håndtering af indsigts-, slette- og berigtigelsesanmodninger fra de registrerede i Løsningen. | G6: Mindstekrav | H6: =IF(G6="Evalueringskrav","Answer",(IF(G6="Krav","Check",(IF(G6="Mindstekrav","Verify",""))))) -> Verify | I6: Ja | L6: Anton | O6: 1. Fully met | V6: Reviewed - Content | W6: =IF(V6="Not Started",0%,IF(V6="Started",50%,IF(V6="Ready for review",70%,IF(V6="Reviewed - Content",80%,IF(V6="Reviewed - Format",90%,IF(V6="Done",100%,"")))))) -> 0.8 | X6: 2026-07-07 | Y6: Cursor / tender-response (batch) | Z6: Met | AA6: Verified | AB6: Verify: Anmodninger fra registrerede — vurderet opfyldt (tool: 1. Fully met). | AD6: docs/tender-reference/extracted/Nationalbanken/Bilag 3.i Leverandørens Løsningsbeskrivelse.txt; docs/tender-reference/extracted/KK Tender tool.txt; docs/tender-reference/extracted/Nationalbanken/Bilag 1.i Leverandørens Løsningsbeskrivelse.txt | AE6: Anton: Confirm verify-tekst; opdatér review status efter tjek. | AG6: Draft | AH6: uim-esdh-full-2026-07-07
A7: 6 | B7: MK-6 | C7: Bilag 1.b | D7: Generelle krav | E7: Håndtering af sletteregler | F7: ESDH-løsningen skal understøtte håndtering af sletteregler, herunder bevaringskoder, for både midlertidig og permanent sletning. ESDH-løsningen skal understøtte, at sletning alene kan foretages af Brugere med de nødvendige rettigheder, herunder at rettigheder til permanent sletning og midlertidig sletning kan adskilles. Sletteregler skal kunne anvendes på alle Entiteter i Løsningen. | G7: Mindstekrav | H7: =IF(G7="Evalueringskrav","Answer",(IF(G7="Krav","Check",(IF(G7="Mindstekrav","Verify",""))))) -> Verify | I7: Ja | L7: Morten | O7: 3. Not able to meet | P7: ADN: "Sletteregler for alle entiteter", kan vi sige at vi har det på kontakter? | Q7: 433881 | R7: Yes | V7: Not Started | W7: =IF(V7="Not Started",0%,IF(V7="Started",50%,IF(V7="Ready for review",70%,IF(V7="Reviewed - Content",80%,IF(V7="Reviewed - Format",90%,IF(V7="Done",100%,"")))))) -> 0 | X7: 2026-07-07 | Y7: Cursor / tender-response | Z7: Partial | AA7: Verified (sag/dokument/fil); Lead (alle Entiteter) | AB7: Sletteregler og bevaringskoder for sag, dokument og fil; midlertidig vs. permanent sletning med adskilte rettigheder (disposal/purge, skjul permanent sletning for sagsbehandlere). Jf. MK-7 og MK-117. | AC7: «Alle Entiteter» er uafklaret: kontakter har sletning (MK-62) men ikke samme sletteregel-model; øvrige entitetstyper ikke dokumenteret. Tool-rating stadig 3. Not able to meet — afstem internt før opdatering af kolonne O. | AD7: HSØ Bilag 2 kassasjon; Ratatoskr Retention (Disposal), Disposal, Purge, File; MK-7, MK-117, MK-14; MK-62 (ikke dækning for MK-6) | AE7: Q&A: præcisér hvad Ordregiver mener med «alle Entiteter». Koordinér med Anton (MK-7/MK-117/MK-14). Opdatér ikke kolonne O før review. | AG7: Draft | AH7: uim-mk6-2026-07-07
A8: 7 | B8: MK-7 | C8: Bilag 1.b | D8: Generelle krav | E8: Opsætning af slettepolitikker | F8: ESDH-løsningen skal understøtte, at Kunden selv uden Leverdørens involvering kan konfigurere slettepolitikker i Løsningens administrationsmodul. | G8: Mindstekrav | H8: =IF(G8="Evalueringskrav","Answer",(IF(G8="Krav","Check",(IF(G8="Mindstekrav","Verify",""))))) -> Verify | I8: Ja | L8: Anton | O8: 1. Fully met | V8: Reviewed - Content | W8: =IF(V8="Not Started",0%,IF(V8="Started",50%,IF(V8="Ready for review",70%,IF(V8="Reviewed - Content",80%,IF(V8="Reviewed - Format",90%,IF(V8="Done",100%,"")))))) -> 0.8 | X8: 2026-07-07 | Y8: Cursor / tender-response (batch) | Z8: Met | AA8: Verified | AB8: Verify: Opsætning af slettepolitikker — vurderet opfyldt (tool: 1. Fully met). | AD8: docs/tender-reference/extracted/KUM-SLKS/Bilag 3 - Kravspecifikation.txt; docs/tender-reference/extracted/Nationalbanken/Bilag 3.i Leverandørens Løsningsbeskrivelse.txt; docs/tender-reference/extracted/KUM-SLKS/Bilag 1 - Tidsplan.txt | AE8: Anton: Confirm verify-tekst; opdatér review status efter tjek. | AG8: Draft | AH8: uim-esdh-full-2026-07-07
A9: 8 | B9: MK-8 | C9: Bilag 1.b | D9: Generelle krav | E9: Klassifikationskoder | F9: ESDH-løsningen skal understøtte, at klassifikationskoder kan oprettes af Administrator, hvortil Kunden valgfrit kan bestemme hvilke klassifikationskoder Løsningen skal indeholde. | G9: Mindstekrav | H9: =IF(G9="Evalueringskrav","Answer",(IF(G9="Krav","Check",(IF(G9="Mindstekrav","Verify",""))))) -> Verify | I9: Ja | L9: Anton | O9: 1. Fully met | V9: Reviewed - Content | W9: =IF(V9="Not Started",0%,IF(V9="Started",50%,IF(V9="Ready for review",70%,IF(V9="Reviewed - Content",80%,IF(V9="Reviewed - Format",90%,IF(V9="Done",100%,"")))))) -> 0.8 | X9: 2026-07-07 | Y9: Cursor / tender-response (batch) | Z9: Met | AA9: Verified | AB9: Verify: Klassifikationskoder — vurderet opfyldt (tool: 1. Fully met). | AD9: docs/tender-reference/extracted/Nationalbanken/Bilag 3.i Leverandørens Løsningsbeskrivelse.txt; docs/tender-reference/extracted/KK Tender tool.txt; docs/tender-reference/extracted/KUM-SLKS/Bilag 3 - Kravspecifikation.txt | AE9: Anton: Confirm verify-tekst; opdatér review status efter tjek. | AG9: Draft | AH9: uim-esdh-full-2026-07-07
A10: 9 | B10: MK-9 | C10: Bilag 1.b | D10: Generelle krav | E10: Deling af Entiteter | F10: ESDH-løsningen skal understøtte, at Entiteter kan deles mellem Brugere, såfremt adgangene tillader dette. | G10: Mindstekrav | H10: =IF(G10="Evalueringskrav","Answer",(IF(G10="Krav","Check",(IF(G10="Mindstekrav","Verify",""))))) -> Verify | I10: Ja | L10: Anton | O10: 1. Fully met | V10: Reviewed - Content | W10: =IF(V10="Not Started",0%,IF(V10="Started",50%,IF(V10="Ready for review",70%,IF(V10="Reviewed - Content",80%,IF(V10="Reviewed - Format",90%,IF(V10="Done",100%,"")))))) -> 0.8 | X10: 2026-07-07 | Y10: Cursor / tender-response (batch) | Z10: Met | AA10: Verified | AB10: Verify: Deling af Entiteter — vurderet opfyldt (tool: 1. Fully met). | AD10: docs/tender-reference/extracted/Nationalbanken/Bilag 3.i Leverandørens Løsningsbeskrivelse.txt; docs/tender-reference/extracted/KK Tender tool.txt; docs/tender-reference/extracted/KUM-SLKS/Bilag 3 - Kravspecifikation.txt | AE10: Anton: Confirm verify-tekst; opdatér review status efter tjek. | AG10: Draft | AH10: uim-esdh-full-2026-07-07
A11: 10 | B11: MK-10 | C11: Bilag 1.b | D11: Generelle krav | E11: Journalplan | F11: ESDH-løsningen skal understøtte en klassisk journalplan eller facetteret journalplan i minimum tre niveauer og emneordsfelter. | G11: Mindstekrav | H11: =IF(G11="Evalueringskrav","Answer",(IF(G11="Krav","Check",(IF(G11="Mindstekrav","Verify",""))))) -> Verify | I11: Ja | L11: Anton | O11: 1. Fully met | V11: Reviewed - Content | W11: =IF(V11="Not Started",0%,IF(V11="Started",50%,IF(V11="Ready for review",70%,IF(V11="Reviewed - Content",80%,IF(V11="Reviewed - Format",90%,IF(V11="Done",100%,"")))))) -> 0.8 | X11: 2026-07-07 | Y11: Cursor / tender-response (batch) | Z11: Met | AA11: Verified | AB11: Verify: Journalplan — vurderet opfyldt (tool: 1. Fully met). | AD11: docs/tender-reference/extracted/KK Tender tool.txt; docs/tender-reference/extracted/Nationalbanken/Bilag 3.i Leverandørens Løsningsbeskrivelse.txt; docs/tender-reference/extracted/KUM-SLKS/Bilag 1 - Tidsplan.txt | AE11: Anton: Confirm verify-tekst; opdatér review status efter tjek. | AG11: Draft | AH11: uim-esdh-full-2026-07-07
A12: 11 | B12: MK-11 | C12: Bilag 1.b | D12: Generelle krav | E12: Oprettelse af brevskabeloner | F12: ESDH-løsningen skal understøtte oprettelse af breve baseret på Kundens brevskabeloner i Dynamic Template. | G12: Mindstekrav | H12: =IF(G12="Evalueringskrav","Answer",(IF(G12="Krav","Check",(IF(G12="Mindstekrav","Verify",""))))) -> Verify | I12: Ja | L12: Anton | N12: Template Connect | O12: 1. Fully met | V12: Reviewed - Content | W12: =IF(V12="Not Started",0%,IF(V12="Started",50%,IF(V12="Ready for review",70%,IF(V12="Reviewed - Content",80%,IF(V12="Reviewed - Format",90%,IF(V12="Done",100%,"")))))) -> 0.8 | X12: 2026-07-07 | Y12: Cursor / tender-response (batch) | Z12: Met | AA12: Verified | AB12: Verify: Oprettelse af brevskabeloner — vurderet opfyldt (tool: 1. Fully met). | AD12: docs/tender-reference/extracted/KK Tender tool.txt; docs/tender-reference/extracted/Nationalbanken/Bilag 3.i Leverandørens Løsningsbeskrivelse.txt; docs/tender-reference/extracted/HSØ/02.00-Tietoevry-SSA-L-Bilag 2-Leverandørens beskrivelse av Tjenesten.txt | AE12: Anton: Confirm verify-tekst; opdatér review status efter tjek. | AG12: Draft | AH12: uim-esdh-full-2026-07-07
A13: 12 | B13: K-1 | C13: Bilag 1.b | D13: Generelle krav | E13: Fejlmeddelelser med handlingsanvisninger | F13: ESDH-løsningen skal understøtte, at fejlmeddelelser i ESDH-løsningen inkluderer handlingsanvisning. | G13: Krav | H13: =IF(G13="Evalueringskrav","Answer",(IF(G13="Krav","Check",(IF(G13="Mindstekrav","Verify",""))))) -> Check | I13: Ja | L13: Torben | O13: 1. Fully met | P13: ADN: We tend to say yes to this requirement - but it comes with a risc, especially if customer uses same External partner in the implementation project | S13: Yes | V13: Ready for review | W13: =IF(V13="Not Started",0%,IF(V13="Started",50%,IF(V13="Ready for review",70%,IF(V13="Reviewed - Content",80%,IF(V13="Reviewed - Format",90%,IF(V13="Done",100%,"")))))) -> 0.7 | X13: 2026-07-07 | Y13: Cursor / tender-response (batch) | Z13: Met | AA13: Lead | AB13: Check: Fejlmeddelelser med handlingsanvisninger — vurderet opfyldt (tool: 1. Fully met). | AC13: ADN: We tend to say yes to this requirement - but it comes with a risc, especially if customer uses same External partner in the implementation project | AD13: docs/tender-reference/extracted/KK Tender tool.txt; docs/product/RFP_Leverandørens_svar_utdrag.txt; docs/tender-reference/extracted/HSØ/02.00-Tietoevry-SSA-L-Bilag 2-Leverandørens beskrivelse av Tjenesten.txt | AE13: Torben: Confirm verify-tekst; opdatér review status efter tjek. | AG13: Draft | AH13: uim-esdh-full-2026-07-07
A14: 13 | B14: MK-12 | C14: Bilag 1.b | D14: Sager | E14: Oprettelse af Sager | F14: ESDH-løsningen skal understøtte oprettelse og registrering af sager. | G14: Mindstekrav | H14: =IF(G14="Evalueringskrav","Answer",(IF(G14="Krav","Check",(IF(G14="Mindstekrav","Verify",""))))) -> Verify | I14: Ja | L14: Anton | O14: 1. Fully met | V14: Reviewed - Content | W14: =IF(V14="Not Started",0%,IF(V14="Started",50%,IF(V14="Ready for review",70%,IF(V14="Reviewed - Content",80%,IF(V14="Reviewed - Format",90%,IF(V14="Done",100%,"")))))) -> 0.8 | X14: 2026-07-07 | Y14: Cursor / tender-response (batch) | Z14: Met | AA14: Verified | AB14: Verify: Oprettelse af Sager — vurderet opfyldt (tool: 1. Fully met). | AD14: docs/tender-reference/extracted/KK Tender tool.txt; docs/tender-reference/extracted/KUM-SLKS/Bilag 3 - 11.8 - Kravspecifikation - Processtyring (1).txt; docs/tender-reference/extracted/KUM-SLKS/Bilag 3 - Kravspecifikation.txt | AE14: Anton: Confirm verify-tekst; opdatér review status efter tjek. | AG14: Draft | AH14: uim-esdh-full-2026-07-07
A15: 14 | B15: MK-13 | C15: Bilag 1.b | D15: Sager | E15: Ændring af sager | F15: ESDH-løsningen skal understøtte ændring af sagens metadata. | G15: Mindstekrav | H15: =IF(G15="Evalueringskrav","Answer",(IF(G15="Krav","Check",(IF(G15="Mindstekrav","Verify",""))))) -> Verify | I15: Ja | L15: Anton | O15: 1. Fully met | V15: Reviewed - Content | W15: =IF(V15="Not Started",0%,IF(V15="Started",50%,IF(V15="Ready for review",70%,IF(V15="Reviewed - Content",80%,IF(V15="Reviewed - Format",90%,IF(V15="Done",100%,"")))))) -> 0.8 | X15: 2026-07-07 | Y15: Cursor / tender-response (batch) | Z15: Met | AA15: Verified | AB15: Verify: Ændring af sager — vurderet opfyldt (tool: 1. Fully met). | AD15: docs/tender-reference/extracted/KK Tender tool.txt; docs/tender-reference/extracted/KUM-SLKS/Bilag 3 - Kravspecifikation.txt; docs/tender-reference/extracted/Nationalbanken/Bilag 3.i Leverandørens Løsningsbeskrivelse.txt | AE15: Anton: Confirm verify-tekst; opdatér review status efter tjek. | AG15: Draft | AH15: uim-esdh-full-2026-07-07
A16: 15 | B16: MK-14 | C16: Bilag 1.b | D16: Sager | E16: Sletning af sager | F16: ESDH-løsningen skal understøtte både midlertidig og permanent sletning af sager. | G16: Mindstekrav | H16: =IF(G16="Evalueringskrav","Answer",(IF(G16="Krav","Check",(IF(G16="Mindstekrav","Verify",""))))) -> Verify | I16: Ja | L16: Anton | O16: 1. Fully met | V16: Reviewed - Content | W16: =IF(V16="Not Started",0%,IF(V16="Started",50%,IF(V16="Ready for review",70%,IF(V16="Reviewed - Content",80%,IF(V16="Reviewed - Format",90%,IF(V16="Done",100%,"")))))) -> 0.8 | X16: 2026-07-07 | Y16: Cursor / tender-response (batch) | Z16: Met | AA16: Verified | AB16: Verify: Sletning af sager — vurderet opfyldt (tool: 1. Fully met). | AD16: docs/tender-reference/extracted/KK Tender tool.txt; docs/tender-reference/extracted/Nationalbanken/Bilag 3.i Leverandørens Løsningsbeskrivelse.txt; docs/product/RFP_Leverandørens_svar_utdrag.txt | AE16: Anton: Confirm verify-tekst; opdatér review status efter tjek. | AG16: Draft | AH16: uim-esdh-full-2026-07-07
A17: 16 | B17: MK-15 | C17: Bilag 1.b | D17: Sager | E17: Status | F17: ESDH-løsningen skal understøtte arbejdet med statusser på en sag, f.eks. 'Passiv', 'Under behandling' og 'Lukket' / 'Afsluttet'. ESDH-løsningen skal understøtte, at Kunden selv kan oprette og vedligeholde statuskoder. | G17: Mindstekrav | H17: =IF(G17="Evalueringskrav","Answer",(IF(G17="Krav","Check",(IF(G17="Mindstekrav","Verify",""))))) -> Verify | I17: Ja | L17: Anton | O17: 1. Fully met | V17: Reviewed - Content | W17: =IF(V17="Not Started",0%,IF(V17="Started",50%,IF(V17="Ready for review",70%,IF(V17="Reviewed - Content",80%,IF(V17="Reviewed - Format",90%,IF(V17="Done",100%,"")))))) -> 0.8 | X17: 2026-07-07 | Y17: Cursor / tender-response (batch) | Z17: Met | AA17: Verified | AB17: Verify: Status — vurderet opfyldt (tool: 1. Fully met). | AD17: docs/tender-reference/extracted/Nationalbanken/Bilag 3.i Leverandørens Løsningsbeskrivelse.txt; docs/tender-reference/extracted/KK Tender tool.txt; docs/tender-reference/extracted/KUM-SLKS/Bilag 3 - Kravspecifikation.txt | AE17: Anton: Confirm verify-tekst; opdatér review status efter tjek. | AG17: Draft | AH17: uim-esdh-full-2026-07-07
A18: 17 | B18: MK-16 | C18: Bilag 1.b | D18: Sager | E18: Sagsnummer | F18: ESDH-løsningen skal understøtte, at hver sag tildeles et unikt sagsnummer automatisk ved oprettelse. | G18: Mindstekrav | H18: =IF(G18="Evalueringskrav","Answer",(IF(G18="Krav","Check",(IF(G18="Mindstekrav","Verify",""))))) -> Verify | I18: Ja | L18: Anton | O18: 1. Fully met | V18: Reviewed - Content | W18: =IF(V18="Not Started",0%,IF(V18="Started",50%,IF(V18="Ready for review",70%,IF(V18="Reviewed - Content",80%,IF(V18="Reviewed - Format",90%,IF(V18="Done",100%,"")))))) -> 0.8 | X18: 2026-07-07 | Y18: Cursor / tender-response (batch) | Z18: Met | AA18: Verified | AB18: Verify: Sagsnummer — vurderet opfyldt (tool: 1. Fully met). | AD18: docs/tender-reference/extracted/Nationalbanken/Bilag 3.i Leverandørens Løsningsbeskrivelse.txt; docs/tender-reference/extracted/KK Tender tool.txt; docs/tender-reference/extracted/KUM-SLKS/Bilag 3 - Kravspecifikation.txt | AE18: Anton: Confirm verify-tekst; opdatér review status efter tjek. | AG18: Draft | AH18: uim-esdh-full-2026-07-07
A19: 18 | B19: MK-17 | C19: Bilag 1.b | D19: Sager | E19: Ændring af sagstyper | F19: ESDH-løsningen skal understøtte, at en Bruger kan ændre sagstype på sager. | G19: Mindstekrav | H19: =IF(G19="Evalueringskrav","Answer",(IF(G19="Krav","Check",(IF(G19="Mindstekrav","Verify",""))))) -> Verify | I19: Ja | L19: Anton | O19: 1. Fully met | V19: Reviewed - Content | W19: =IF(V19="Not Started",0%,IF(V19="Started",50%,IF(V19="Ready for review",70%,IF(V19="Reviewed - Content",80%,IF(V19="Reviewed - Format",90%,IF(V19="Done",100%,"")))))) -> 0.8 | X19: 2026-07-07 | Y19: Cursor / tender-response (batch) | Z19: Met | AA19: Verified | AB19: Verify: Ændring af sagstyper — vurderet opfyldt (tool: 1. Fully met). | AD19: docs/tender-reference/extracted/KK Tender tool.txt; docs/tender-reference/extracted/KUM-SLKS/Bilag 3 - Kravspecifikation.txt; docs/tender-reference/extracted/Nationalbanken/Bilag 3.i Leverandørens Løsningsbeskrivelse.txt | AE19: Anton: Confirm verify-tekst; opdatér review status efter tjek. | AG19: Draft | AH19: uim-esdh-full-2026-07-07
A20: 19 | B20: MK-18 | C20: Bilag 1.b | D20: Sager | E20: Sagens frister | F20: ESDH-løsningen skal understøtte, at der kan indsættes, rettes og fjernes frister på alle sagstyper. Fristen skal som minimum bestå af en fristtype, fristdato og fristansvarlig. | G20: Mindstekrav | H20: =IF(G20="Evalueringskrav","Answer",(IF(G20="Krav","Check",(IF(G20="Mindstekrav","Verify",""))))) -> Verify | I20: Ja | L20: Anton | O20: 1. Fully met | P20: ADN:Configure field called "Fristtype" | V20: Reviewed - Content | W20: =IF(V20="Not Started",0%,IF(V20="Started",50%,IF(V20="Ready for review",70%,IF(V20="Reviewed - Content",80%,IF(V20="Reviewed - Format",90%,IF(V20="Done",100%,"")))))) -> 0.8 | X20: 2026-07-07 | Y20: Cursor / tender-response (batch) | Z20: Met | AA20: Verified | AB20: Verify: Sagens frister — vurderet opfyldt (tool: 1. Fully met). | AC20: ADN:Configure field called "Fristtype" | AD20: docs/tender-reference/extracted/Nationalbanken/Bilag 3.i Leverandørens Løsningsbeskrivelse.txt; docs/tender-reference/extracted/KUM-SLKS/Bilag 3 - Kravspecifikation.txt; docs/tender-reference/extracted/KK Tender tool.txt | AE20: Anton: Confirm verify-tekst; opdatér review status efter tjek. | AG20: Draft | AH20: uim-esdh-full-2026-07-07
A21: 20 | B21: MK-19 | C21: Bilag 1.b | D21: Sager | E21: Afdelingsspecifikke frister | F21: ESDH-løsningen skal understøtte, at Brugere kan indsætte, rette og fjerne én eller flere afdelingsspecifikke frister på sager. | G21: Mindstekrav | H21: =IF(G21="Evalueringskrav","Answer",(IF(G21="Krav","Check",(IF(G21="Mindstekrav","Verify",""))))) -> Verify | I21: Ja | L21: Anton | O21: 1. Fully met | V21: Reviewed - Content | W21: =IF(V21="Not Started",0%,IF(V21="Started",50%,IF(V21="Ready for review",70%,IF(V21="Reviewed - Content",80%,IF(V21="Reviewed - Format",90%,IF(V21="Done",100%,"")))))) -> 0.8 | X21: 2026-07-07 | Y21: Cursor / tender-response (batch) | Z21: Met | AA21: Verified | AB21: Verify: Afdelingsspecifikke frister — vurderet opfyldt (tool: 1. Fully met). | AD21: docs/tender-reference/extracted/KUM-SLKS/Bilag 3 - Kravspecifikation.txt; docs/tender-reference/extracted/Nationalbanken/Bilag 3.i Leverandørens Løsningsbeskrivelse.txt; docs/tender-reference/extracted/KK Tender tool.txt | AE21: Anton: Confirm verify-tekst; opdatér review status efter tjek. | AG21: Draft | AH21: uim-esdh-full-2026-07-07
A22: 21 | B22: MK-20 | C22: Bilag 1.b | D22: Sager | E22: Samlesager | F22: ESDH-løsningen skal understøtte oprettelse af samlesager. Det skal være muligt for Brugeren at tilknytte enkle sager til samlesager. | G22: Mindstekrav | H22: =IF(G22="Evalueringskrav","Answer",(IF(G22="Krav","Check",(IF(G22="Mindstekrav","Verify",""))))) -> Verify | I22: Ja | L22: Anton | O22: 1. Fully met | V22: Reviewed - Content | W22: =IF(V22="Not Started",0%,IF(V22="Started",50%,IF(V22="Ready for review",70%,IF(V22="Reviewed - Content",80%,IF(V22="Reviewed - Format",90%,IF(V22="Done",100%,"")))))) -> 0.8 | X22: 2026-07-07 | Y22: Cursor / tender-response (batch) | Z22: Met | AA22: Verified | AB22: Verify: Samlesager — vurderet opfyldt (tool: 1. Fully met). | AD22: docs/tender-reference/extracted/Nationalbanken/Bilag 3.i Leverandørens Løsningsbeskrivelse.txt; docs/tender-reference/extracted/KK Tender tool.txt; docs/tender-reference/extracted/KUM-SLKS/Bilag 3 - 11.8 - Kravspecifikation - Processtyring (1).txt | AE22: Anton: Confirm verify-tekst; opdatér review status efter tjek. | AG22: Draft | AH22: uim-esdh-full-2026-07-07
A23: 22 | B23: MK-21 | C23: Bilag 1.b | D23: Sager | E23: Oprettelse af hierarkisk samling | F23: ESDH-løsningen skal understøtte oprettelsesfunktion til organisering og hierarkisk visning af samling af relaterede sager. | G23: Mindstekrav | H23: =IF(G23="Evalueringskrav","Answer",(IF(G23="Krav","Check",(IF(G23="Mindstekrav","Verify",""))))) -> Verify | I23: Ja | L23: Eva | O23: 1. Fully met | P23: ADN: Im unsure what they mean with this requirement. - is this "Træstrukturen"? | V23: Ready for review | W23: =IF(V23="Not Started",0%,IF(V23="Started",50%,IF(V23="Ready for review",70%,IF(V23="Reviewed - Content",80%,IF(V23="Reviewed - Format",90%,IF(V23="Done",100%,"")))))) -> 0.7 | X23: 2026-07-07 | Y23: Cursor / tender-response (batch) | Z23: Met | AA23: Verified | AB23: Verify: Oprettelse af hierarkisk samling — vurderet opfyldt (tool: 1. Fully met). | AC23: ADN: Im unsure what they mean with this requirement. - is this "Træstrukturen"? | AD23: docs/tender-reference/extracted/Nationalbanken/Bilag 3.i Leverandørens Løsningsbeskrivelse.txt; docs/tender-reference/extracted/KK Tender tool.txt; docs/tender-reference/extracted/KUM-SLKS/Bilag 3 - Kravspecifikation.txt | AE23: Eva: Confirm verify-tekst; opdatér review status efter tjek. | AG23: Draft | AH23: uim-esdh-full-2026-07-07
A24: 23 | B24: MK-22 | C24: Bilag 1.b | D24: Sager | E24: Referencer | F24: ESDH-løsningen skal understøtte oprettelse af referencer mellem sager ved at etablere links mellem sager. Det skal fremgå tydeligt af den enkelte sag, at den er relateret til en anden. | G24: Mindstekrav | H24: =IF(G24="Evalueringskrav","Answer",(IF(G24="Krav","Check",(IF(G24="Mindstekrav","Verify",""))))) -> Verify | I24: Ja | L24: Anton | O24: 1. Fully met | V24: Reviewed - Content | W24: =IF(V24="Not Started",0%,IF(V24="Started",50%,IF(V24="Ready for review",70%,IF(V24="Reviewed - Content",80%,IF(V24="Reviewed - Format",90%,IF(V24="Done",100%,"")))))) -> 0.8 | X24: 2026-07-07 | Y24: Cursor / tender-response (batch) | Z24: Met | AA24: Verified | AB24: Verify: Referencer — vurderet opfyldt (tool: 1. Fully met). | AD24: docs/tender-reference/extracted/KK Tender tool.txt; docs/tender-reference/extracted/Nationalbanken/Bilag 3.i Leverandørens Løsningsbeskrivelse.txt; docs/tender-reference/extracted/KUM-SLKS/Bilag 3 - Kravspecifikation.txt | AE24: Anton: Confirm verify-tekst; opdatér review status efter tjek. | AG24: Draft | AH24: uim-esdh-full-2026-07-07
A25: 24 | B25: MK-23 | C25: Bilag 1.b | D25: Sager | E25: Fremvisning af parter | F25: ESDH-løsningen skal understøtte, at sagens parter kan vises enten i sagens overbliksbillede eller i en dedikeret fane. | G25: Mindstekrav | H25: =IF(G25="Evalueringskrav","Answer",(IF(G25="Krav","Check",(IF(G25="Mindstekrav","Verify",""))))) -> Verify | I25: Ja | L25: Anton | O25: 1. Fully met | V25: Reviewed - Content | W25: =IF(V25="Not Started",0%,IF(V25="Started",50%,IF(V25="Ready for review",70%,IF(V25="Reviewed - Content",80%,IF(V25="Reviewed - Format",90%,IF(V25="Done",100%,"")))))) -> 0.8 | X25: 2026-07-07 | Y25: Cursor / tender-response (batch) | Z25: Met | AA25: Verified | AB25: Verify: Fremvisning af parter — vurderet opfyldt (tool: 1. Fully met). | AD25: docs/tender-reference/extracted/Nationalbanken/Bilag 3.i Leverandørens Løsningsbeskrivelse.txt; docs/tender-reference/extracted/KUM-SLKS/Bilag 3 - Kravspecifikation.txt; docs/tender-reference/extracted/KK Tender tool.txt | AE25: Anton: Confirm verify-tekst; opdatér review status efter tjek. | AG25: Draft | AH25: uim-esdh-full-2026-07-07
A26: 25 | B26: MK-24 | C26: Bilag 1.b | D26: Sager | E26: Partsrolle | F26: ESDH-løsningen skal understøtte, at en kontakt kan tilknyttes til en sag og at kontakten kan have en konkret partsrolle på sagen. | G26: Mindstekrav | H26: =IF(G26="Evalueringskrav","Answer",(IF(G26="Krav","Check",(IF(G26="Mindstekrav","Verify",""))))) -> Verify | I26: Ja | L26: Anton | O26: 1. Fully met | V26: Reviewed - Content | W26: =IF(V26="Not Started",0%,IF(V26="Started",50%,IF(V26="Ready for review",70%,IF(V26="Reviewed - Content",80%,IF(V26="Reviewed - Format",90%,IF(V26="Done",100%,"")))))) -> 0.8 | X26: 2026-07-07 | Y26: Cursor / tender-response (batch) | Z26: Met | AA26: Verified | AB26: Verify: Partsrolle — vurderet opfyldt (tool: 1. Fully met). | AD26: docs/tender-reference/extracted/KUM-SLKS/Bilag 3 - Kravspecifikation.txt; docs/tender-reference/extracted/Nationalbanken/Bilag 3.i Leverandørens Løsningsbeskrivelse.txt; docs/product/RFP_Leverandørens_svar_utdrag.txt | AE26: Anton: Confirm verify-tekst; opdatér review status efter tjek. | AG26: Draft | AH26: uim-esdh-full-2026-07-07
A27: 26 | B27: MK-25 | C27: Bilag 1.b | D27: Sager | E27: Intern overdragelse af sagsansvar | F27: ESDH-løsningen skal understøtte, at en sag kan overdrages/flyttes til en anden sagsbehandler eller et andet team i organisationen. | G27: Mindstekrav | H27: =IF(G27="Evalueringskrav","Answer",(IF(G27="Krav","Check",(IF(G27="Mindstekrav","Verify",""))))) -> Verify | I27: Ja | L27: Anton | O27: 1. Fully met | V27: Reviewed - Content | W27: =IF(V27="Not Started",0%,IF(V27="Started",50%,IF(V27="Ready for review",70%,IF(V27="Reviewed - Content",80%,IF(V27="Reviewed - Format",90%,IF(V27="Done",100%,"")))))) -> 0.8 | X27: 2026-07-07 | Y27: Cursor / tender-response (batch) | Z27: Met | AA27: Verified | AB27: Verify: Intern overdragelse af sagsansvar — vurderet opfyldt (tool: 1. Fully met). | AD27: docs/tender-reference/extracted/KUM-SLKS/Bilag 3 - Kravspecifikation.txt; docs/product/RFP_Leverandørens_svar_utdrag.txt; docs/tender-reference/extracted/KK Tender tool.txt | AE27: Anton: Confirm verify-tekst; opdatér review status efter tjek. | AG27: Draft | AH27: uim-esdh-full-2026-07-07
A28: 27 | B28: MK-26 | C28: Bilag 1.b | D28: Sager | E28: Genåbning og opdatering af lukkede sager | F28: ESDH-løsningen skal understøtte, at en formelt afsluttet og lukket sag kan genåbnes af en Bruger, hvis der er behov for at opdatere sagsdata. Sager afleveret til Rigsarkivet skal være undtaget, og skal ikke kunne genåbnes efter aflevering. | G28: Mindstekrav | H28: =IF(G28="Evalueringskrav","Answer",(IF(G28="Krav","Check",(IF(G28="Mindstekrav","Verify",""))))) -> Verify | I28: Ja | L28: Anton | O28: 1. Fully met | P28: ADN: Configure historic cases with closed Matrix | V28: Reviewed - Content | W28: =IF(V28="Not Started",0%,IF(V28="Started",50%,IF(V28="Ready for review",70%,IF(V28="Reviewed - Content",80%,IF(V28="Reviewed - Format",90%,IF(V28="Done",100%,"")))))) -> 0.8 | X28: 2026-07-07 | Y28: Cursor / tender-response (batch) | Z28: Met | AA28: Verified | AB28: Verify: Genåbning og opdatering af lukkede sager — vurderet opfyldt (tool: 1. Fully met). | AC28: ADN: Configure historic cases with closed Matrix | AD28: docs/tender-reference/extracted/Nationalbanken/Bilag 3.i Leverandørens Løsningsbeskrivelse.txt; docs/tender-reference/extracted/KK Tender tool.txt; docs/tender-reference/extracted/KUM-SLKS/Bilag 3 - Kravspecifikation.txt | AE28: Anton: Confirm verify-tekst; opdatér review status efter tjek. | AG28: Draft | AH28: uim-esdh-full-2026-07-07
A29: 28 | B29: MK-27 | C29: Bilag 1.b | D29: Sager | E29: Sagskopi | F29: ESDH-løsningen skal understøtte oprettelse af en sagskopi, hvor den oprindelige sags metadata overføres til sagskopien. I forbindelse med oprettelse af sagskopien skal Brugeren valgfrit kunne vælge om sagens parter, Dokumenter og øvrigt metadata skal overføres til sagskopien. Metadata på begge sager skal kunne redigeres efterfølgende. | G29: Mindstekrav | H29: =IF(G29="Evalueringskrav","Answer",(IF(G29="Krav","Check",(IF(G29="Mindstekrav","Verify",""))))) -> Verify | I29: Ja | L29: Anton | O29: 1. Fully met | P29: ADN: copy documents is part of eDoc merger, so Yes | V29: Reviewed - Content | W29: =IF(V29="Not Started",0%,IF(V29="Started",50%,IF(V29="Ready for review",70%,IF(V29="Reviewed - Content",80%,IF(V29="Reviewed - Format",90%,IF(V29="Done",100%,"")))))) -> 0.8 | X29: 2026-07-07 | Y29: Cursor / tender-response (batch) | Z29: Met | AA29: Verified | AB29: Verify: Sagskopi — vurderet opfyldt (tool: 1. Fully met). | AC29: ADN: copy documents is part of eDoc merger, so Yes | AD29: docs/tender-reference/extracted/Nationalbanken/Bilag 3.i Leverandørens Løsningsbeskrivelse.txt; docs/tender-reference/extracted/KK Tender tool.txt; docs/tender-reference/extracted/KUM-SLKS/Bilag 3 - Kravspecifikation.txt | AE29: Anton: Confirm verify-tekst; opdatér review status efter tjek. | AG29: Draft | AH29: uim-esdh-full-2026-07-07
A30: 29 | B30: MK-28 | C30: Bilag 1.b | D30: Sager | E30: Noter | F30: ESDH-løsningen skal understøtte, at der kan oprettes noter på sager. Oplysninger om sagsbehandler, dato og klokkeslæt skal fremgå af noten. Alle Brugere med adgang til sagen skal kunne se agere på noten i sagsbehandlingen. | G30: Mindstekrav | H30: =IF(G30="Evalueringskrav","Answer",(IF(G30="Krav","Check",(IF(G30="Mindstekrav","Verify",""))))) -> Verify | I30: Ja | L30: Anton | O30: 1. Fully met | V30: Reviewed - Content | W30: =IF(V30="Not Started",0%,IF(V30="Started",50%,IF(V30="Ready for review",70%,IF(V30="Reviewed - Content",80%,IF(V30="Reviewed - Format",90%,IF(V30="Done",100%,"")))))) -> 0.8 | X30: 2026-07-07 | Y30: Cursor / tender-response (batch) | Z30: Met | AA30: Verified | AB30: Verify: Noter — vurderet opfyldt (tool: 1. Fully met). | AD30: docs/tender-reference/extracted/Nationalbanken/Bilag 3.i Leverandørens Løsningsbeskrivelse.txt; docs/tender-reference/extracted/KK Tender tool.txt; docs/tender-reference/extracted/KUM-SLKS/Bilag 3 - Kravspecifikation.txt | AE30: Anton: Confirm verify-tekst; opdatér review status efter tjek. | AG30: Draft | AH30: uim-esdh-full-2026-07-07
A31: 30 | B31: MK-29 | C31: Bilag 1.b | D31: Sager | E31: Journalisering | F31: ESDH-løsningen skal understøtte, at Brugere manuelt kan journalisere og gemme Dokumenter, korrespondancer samt interne og eksterne beskeder på sager. | G31: Mindstekrav | H31: =IF(G31="Evalueringskrav","Answer",(IF(G31="Krav","Check",(IF(G31="Mindstekrav","Verify",""))))) -> Verify | I31: Ja | L31: Anton | O31: 1. Fully met | V31: Reviewed - Content | W31: =IF(V31="Not Started",0%,IF(V31="Started",50%,IF(V31="Ready for review",70%,IF(V31="Reviewed - Content",80%,IF(V31="Reviewed - Format",90%,IF(V31="Done",100%,"")))))) -> 0.8 | X31: 2026-07-07 | Y31: Cursor / tender-response (batch) | Z31: Met | AA31: Verified | AB31: Verify: Journalisering — vurderet opfyldt (tool: 1. Fully met). | AD31: docs/tender-reference/extracted/KK Tender tool.txt; docs/tender-reference/extracted/Nationalbanken/Bilag 3.i Leverandørens Løsningsbeskrivelse.txt; docs/tender-reference/extracted/KUM-SLKS/Bilag 3 - Kravspecifikation.txt | AE31: Anton: Confirm verify-tekst; opdatér review status efter tjek. | AG31: Draft | AH31: uim-esdh-full-2026-07-07
A32: 31 | B32: MK-30 | C32: Bilag 1.b | D32: Sager | E32: Præsentation af hierarkiske samlinger | F32: ESDH-løsningen skal understøtte visning af hierarkiske samlinger af relaterede sager fra søgningslister og visningslister. | G32: Mindstekrav | H32: =IF(G32="Evalueringskrav","Answer",(IF(G32="Krav","Check",(IF(G32="Mindstekrav","Verify",""))))) -> Verify | I32: Ja | L32: Eva | O32: 3. Not able to meet | P32: ADN: Det er kludret formuleret - men jeg tolker det til, at de fra en søgning på et projekt, skal kunne se relaterede sager i resultatlisterne.. Det er udfordrende | Q32: 433877 | R32: Yes | V32: Not Started | W32: =IF(V32="Not Started",0%,IF(V32="Started",50%,IF(V32="Ready for review",70%,IF(V32="Reviewed - Content",80%,IF(V32="Reviewed - Format",90%,IF(V32="Done",100%,"")))))) -> 0 | X32: 2026-07-07 | Y32: Cursor / tender-response (MCP-enriched) | Z32: Not met | AA32: Lead | AB32: Verify: Præsentation af hierarkiske samlinger — gap ift. kravtekst; eskalér commitment eller afklaring. | AC32: ADN: Det er kludret formuleret - men jeg tolker det til, at de fra en søgning på et projekt, skal kunne se relaterede sager i resultatlisterne.. Det er udfordrende | Red flag: Det er kludret formuleret - men jeg tolker det til, at de fra en søgning på et projekt, skal kunne se relaterede sager i resultatlisterne.. Det er udfordrende | AD32: Wiki: EArchive 360°; Setup of Continuous Transfer | AE32: Eva: Commitment/no-bid beslutning; overvej Q&A til ordregiver. | AG32: Draft | AH32: uim-esdh-full-2026-07-07
A33: 32 | B33: MK-31 | C33: Bilag 1.b | D33: Sager | E33: Antal frister | F33: ESDH-løsningen skal understøtte, at en sag kan have flere frister tilknyttet. Fristerne skal vises på en logisk og overskuelig måde i brugergrænsefladen, så Brugeren nemt kan se fristtype, status og tidspunkt for kommende frister. | G33: Mindstekrav | H33: =IF(G33="Evalueringskrav","Answer",(IF(G33="Krav","Check",(IF(G33="Mindstekrav","Verify",""))))) -> Verify | I33: Ja | L33: Anton | O33: 1. Fully met | V33: Reviewed - Content | W33: =IF(V33="Not Started",0%,IF(V33="Started",50%,IF(V33="Ready for review",70%,IF(V33="Reviewed - Content",80%,IF(V33="Reviewed - Format",90%,IF(V33="Done",100%,"")))))) -> 0.8 | X33: 2026-07-07 | Y33: Cursor / tender-response (batch) | Z33: Met | AA33: Verified | AB33: Verify: Antal frister — vurderet opfyldt (tool: 1. Fully met). | AD33: docs/tender-reference/extracted/Nationalbanken/Bilag 3.i Leverandørens Løsningsbeskrivelse.txt; docs/tender-reference/extracted/KK Tender tool.txt; docs/tender-reference/extracted/KUM-SLKS/Bilag 3 - Kravspecifikation.txt | AE33: Anton: Confirm verify-tekst; opdatér review status efter tjek. | AG33: Draft | AH33: uim-esdh-full-2026-07-07
A34: 33 | B34: MK-32 | C34: Bilag 1.b | D34: Sager | E34: Noter – Journalisering på sag | F34: ESDH-løsningen skal understøtte, at noter kan konverteres til et Dokument med en tilhørende Fil, som kan journaliseres på den tilknyttede sag. | G34: Mindstekrav | H34: =IF(G34="Evalueringskrav","Answer",(IF(G34="Krav","Check",(IF(G34="Mindstekrav","Verify",""))))) -> Verify | I34: Ja | L34: Anton | O34: 1. Fully met | P34: ADN: Configure Case Note summary functionality | V34: Reviewed - Content | W34: =IF(V34="Not Started",0%,IF(V34="Started",50%,IF(V34="Ready for review",70%,IF(V34="Reviewed - Content",80%,IF(V34="Reviewed - Format",90%,IF(V34="Done",100%,"")))))) -> 0.8 | X34: 2026-07-07 | Y34: Cursor / tender-response (batch) | Z34: Met | AA34: Verified | AB34: Verify: Noter – Journalisering på sag — vurderet opfyldt (tool: 1. Fully met). | AC34: ADN: Configure Case Note summary functionality | AD34: docs/tender-reference/extracted/KK Tender tool.txt; docs/tender-reference/extracted/KUM-SLKS/Bilag 3 - Kravspecifikation.txt; docs/tender-reference/extracted/Nationalbanken/Bilag 3.i Leverandørens Løsningsbeskrivelse.txt | AE34: Anton: Confirm verify-tekst; opdatér review status efter tjek. | AG34: Draft | AH34: uim-esdh-full-2026-07-07
A35: 34 | B35: MK-33 | C35: Bilag 1.b | D35: Dokumenter | E35: Behandling af Dokumenter | F35: ESDH-løsningen skal understøtte grundlæggende dokumenthåndtering, herunder oprettelse, redigering, versionsstyring og tilknytning af relevante metadata. | G35: Mindstekrav | H35: =IF(G35="Evalueringskrav","Answer",(IF(G35="Krav","Check",(IF(G35="Mindstekrav","Verify",""))))) -> Verify | I35: Ja | L35: Anton | O35: 1. Fully met | V35: Reviewed - Content | W35: =IF(V35="Not Started",0%,IF(V35="Started",50%,IF(V35="Ready for review",70%,IF(V35="Reviewed - Content",80%,IF(V35="Reviewed - Format",90%,IF(V35="Done",100%,"")))))) -> 0.8 | X35: 2026-07-07 | Y35: Cursor / tender-response (batch) | Z35: Met | AA35: Verified | AB35: Verify: Behandling af Dokumenter — vurderet opfyldt (tool: 1. Fully met). | AD35: docs/tender-reference/extracted/Nationalbanken/Bilag 3.i Leverandørens Løsningsbeskrivelse.txt; docs/tender-reference/extracted/KK Tender tool.txt; docs/tender-reference/extracted/KUM-SLKS/Bilag 3 - Kravspecifikation.txt | AE35: Anton: Confirm verify-tekst; opdatér review status efter tjek. | AG35: Draft | AH35: uim-esdh-full-2026-07-07
A36: 35 | B36: MK-34 | C36: Bilag 1.b | D36: Dokumenter | E36: Oprettelse af felter | F36: ESDH-løsningen skal understøtte, at felter kan oprettes og relateres til Dokumenter af Kunden. | G36: Mindstekrav | H36: =IF(G36="Evalueringskrav","Answer",(IF(G36="Krav","Check",(IF(G36="Mindstekrav","Verify",""))))) -> Verify | I36: Ja | L36: Anton | O36: 1. Fully met | V36: Reviewed - Content | W36: =IF(V36="Not Started",0%,IF(V36="Started",50%,IF(V36="Ready for review",70%,IF(V36="Reviewed - Content",80%,IF(V36="Reviewed - Format",90%,IF(V36="Done",100%,"")))))) -> 0.8 | X36: 2026-07-07 | Y36: Cursor / tender-response (batch) | Z36: Met | AA36: Verified | AB36: Verify: Oprettelse af felter — vurderet opfyldt (tool: 1. Fully met). | AD36: docs/tender-reference/extracted/KUM-SLKS/Bilag 3 - Kravspecifikation.txt; docs/tender-reference/extracted/KK Tender tool.txt; docs/tender-reference/extracted/KUM-SLKS/Bilag 3 - 11.8 - Kravspecifikation - Processtyring (1).txt | AE36: Anton: Confirm verify-tekst; opdatér review status efter tjek. | AG36: Draft | AH36: uim-esdh-full-2026-07-07
A37: 36 | B37: MK-35 | C37: Bilag 1.b | D37: Dokumenter | E37: Unikt ID | F37: ESDH-løsningen skal understøtte, at alle Dokumenter, Filer, Hoveddokumenter og Bilag har hver deres unikke ID, som skal være synligt i brugergrænsefladen. | G37: Mindstekrav | H37: =IF(G37="Evalueringskrav","Answer",(IF(G37="Krav","Check",(IF(G37="Mindstekrav","Verify",""))))) -> Verify | I37: Ja | L37: Anton | O37: 1. Fully met | P37: ADN: Hvornår er noget ”synligt i brugergrænsefladen”… vi har recno på filer, men de kræver ”vis egenskaber” for at være synlige. Tjek definitionsbilag for ordet "brugergrænsefladen" Maksimeret visning - ny visning | V37: Reviewed - Content | W37: =IF(V37="Not Started",0%,IF(V37="Started",50%,IF(V37="Ready for review",70%,IF(V37="Reviewed - Content",80%,IF(V37="Reviewed - Format",90%,IF(V37="Done",100%,"")))))) -> 0.8 | X37: 2026-07-07 | Y37: Cursor / tender-response (MCP-enriched) | Z37: Met | AA37: Lead | AB37: Verify: Unikt ID — vurderet opfyldt (tool: 1. Fully met). | AC37: ADN: Hvornår er noget ”synligt i brugergrænsefladen”… vi har recno på filer, men de kræver ”vis egenskaber” for at være synlige. Tjek definitionsbilag for ordet "brugergrænsefladen" Maksimeret visning - ny visning | Red flag: Hvornår er noget ”synligt i brugergrænsefladen”… vi har recno på filer, men de kræver ”vis egenskaber” for at være synlige. | AD37: Wiki: 360° AutoSaver - Technical documentation; Process Engine - Manual | AE37: Anton: Confirm verify-tekst; opdatér review status efter tjek. | AG37: Draft | AH37: uim-esdh-full-2026-07-07
A38: 37 | B38: MK-36 | C38: Bilag 1.b | D38: Dokumenter | E38: Relation mellem sag og Dokument | F38: ESDH-løsningen skal understøtte en obligatorisk relation mellem sag og Dokument. | G38: Mindstekrav | H38: =IF(G38="Evalueringskrav","Answer",(IF(G38="Krav","Check",(IF(G38="Mindstekrav","Verify",""))))) -> Verify | I38: Ja | L38: Anton | O38: 1. Fully met | V38: Reviewed - Content | W38: =IF(V38="Not Started",0%,IF(V38="Started",50%,IF(V38="Ready for review",70%,IF(V38="Reviewed - Content",80%,IF(V38="Reviewed - Format",90%,IF(V38="Done",100%,"")))))) -> 0.8 | X38: 2026-07-07 | Y38: Cursor / tender-response (batch) | Z38: Met | AA38: Verified | AB38: Verify: Relation mellem sag og Dokument — vurderet opfyldt (tool: 1. Fully met). | AD38: docs/tender-reference/extracted/KK Tender tool.txt; docs/tender-reference/extracted/KUM-SLKS/Bilag 3 - Kravspecifikation.txt; docs/tender-reference/extracted/Nationalbanken/Bilag 3.i Leverandørens Løsningsbeskrivelse.txt | AE38: Anton: Confirm verify-tekst; opdatér review status efter tjek. | AG38: Draft | AH38: uim-esdh-full-2026-07-07
A39: 38 | B39: MK-37 | C39: Bilag 1.b | D39: Dokumenter | E39: Bilag | F39: ESDH-løsningen skal understøtte, at et Hoveddokument kan have et eller flere Bilag. | G39: Mindstekrav | H39: =IF(G39="Evalueringskrav","Answer",(IF(G39="Krav","Check",(IF(G39="Mindstekrav","Verify",""))))) -> Verify | I39: Ja | L39: Anton | O39: 1. Fully met | V39: Reviewed - Content | W39: =IF(V39="Not Started",0%,IF(V39="Started",50%,IF(V39="Ready for review",70%,IF(V39="Reviewed - Content",80%,IF(V39="Reviewed - Format",90%,IF(V39="Done",100%,"")))))) -> 0.8 | X39: 2026-07-07 | Y39: Cursor / tender-response (batch) | Z39: Met | AA39: Verified | AB39: Verify: Bilag — vurderet opfyldt (tool: 1. Fully met). | AD39: docs/product/RFP_Leverandørens_svar_utdrag.txt; docs/tender-reference/extracted/KUM-SLKS/Bilag 3 - Kravspecifikation.txt; docs/tender-reference/extracted/NND/02.01-Tieto-Bilag 2-Vedlegg-Leverandørens utfyllende svar til kravtabell.txt | AE39: Anton: Confirm verify-tekst; opdatér review status efter tjek. | AG39: Draft | AH39: uim-esdh-full-2026-07-07
A40: 39 | B40: MK-38 | C40: Bilag 1.b | D40: Dokumenter | E40: Valg af Hoveddokument og Bilag | F40: ESDH-løsningen skal understøtte, at Brugeren kan vælge, hvilken Fil der skal være Hoveddokument, og hvilke Filer der skal tilknyttes som Bilag. | G40: Mindstekrav | H40: =IF(G40="Evalueringskrav","Answer",(IF(G40="Krav","Check",(IF(G40="Mindstekrav","Verify",""))))) -> Verify | I40: Ja | L40: Anton | O40: 1. Fully met | V40: Reviewed - Content | W40: =IF(V40="Not Started",0%,IF(V40="Started",50%,IF(V40="Ready for review",70%,IF(V40="Reviewed - Content",80%,IF(V40="Reviewed - Format",90%,IF(V40="Done",100%,"")))))) -> 0.8 | X40: 2026-07-07 | Y40: Cursor / tender-response (batch) | Z40: Met | AA40: Verified | AB40: Verify: Valg af Hoveddokument og Bilag — vurderet opfyldt (tool: 1. Fully met). | AD40: docs/tender-reference/extracted/KUM-SLKS/Bilag 3 - Kravspecifikation.txt; docs/tender-reference/extracted/Nationalbanken/Bilag 3.i Leverandørens Løsningsbeskrivelse.txt; docs/product/RFP_Leverandørens_svar_utdrag.txt | AE40: Anton: Confirm verify-tekst; opdatér review status efter tjek. | AG40: Draft | AH40: uim-esdh-full-2026-07-07
...

Sheet Red flags
A1: Krav nr. | B1: Kravtekst | C1: Kommentar
A2: MK-30 | B2: MK-30 | C2: Det er kludret formuleret - men jeg tolker det til, at de fra en søgning på et projekt, skal kunne se relaterede sager i resultatlisterne.. Det er udfordrende
A3: MK-35 | B3: ESDH-løsningen skal understøtte, at alle Dokumenter, Filer, Hoveddokumenter og Bilag har hver deres unikke ID, som skal være synligt i brugergrænsefladen. | C3: Hvornår er noget ”synligt i brugergrænsefladen”… vi har recno på filer, men de kræver ”vis egenskaber” for at være synlige.
A4: MK-49 | B4: ESDH-løsningen skal understøtte en integreret dokumentviewer i brugergrænsefladen. Løsningen skal understøtte forhåndsvisning af Dokumenter fra sager, søgninger og listevisninger. ESDH-løsningen skal understøtte, at Brugeren får præsenteret Dokumentets tekst/indhold direkte i Løsningen. | C4: ”Direkte” er problematisk, hvis det forbyder os fra et nyt vindue.
A5: MK-50 | B5: ESDH-løsningen skal understøtte, at Brugeren kan navigere og scrolle i dokument- og fillistevisninger, og at forhåndsvisningen automatisk opdateres og viser det Dokument/Fil, som Brugeren har navigeret til. | C5: Vores forhåndsvisning ”opdateres ikke automatisk”. Kræver aktivt klik på det dokument/fil der ønskes forhåndsvist.
A6: MK-56 | B6: ESDH-løsningen skal understøtte, at en Bruger ikke kan oprette en kontakt, hvis kontaktens unikke ID allerede findes i kontaktregisteret. | C6: Vi advarer, men vi forbyder ikke. CPR/CVR er ikke så unikt at det ikke kan duplikeres.
A7: MK-66 | B7: ESDH-løsningen skal understøtte, at der kan søges på alle standard- og Kundeoprettede felter på samme tid i ESDH-løsningen. | C7: Det her krav er formuleret uden logiske begræsninger mellem entiteter, hvilke tikke giver mening. Det kan vi ikke understøtte.
A8: MK-68 | B8: Trunkering i avanceret søgning | C8: Det her lugter af at være givet titlen her, fordi de ved vi ikke kan i den avancerede søgning - men kravteksten indeholder det ikke, og derfor bør vi være OK med kravet
A9: MK-70 | B9: ESDH-løsningen skal understøtte, at alle felter kan vises i søgeresultaternes visningslister. | C9: ”Alle felter” - godt nok afgrænset til søgeresultater, men stadig en stor risc, fra en ondsindet kunde.
A10: MK-74 | B10: ESDH-løsningen skal understøtte, at Kunden kan opsætte og konfigurere søgebilleder for alle Løsningens standard- og Kundeoprettede Entiteter. | C10: Det understøtter vi ikke.
A11: MK-75 | B11: ESDH-løsningen skal understøtte, at Kunden selv kan definere og konfigurere, hvilke standard- og Kundeoprettede felter søgebilledet skal indeholde. | C11: Det understøtter vi ikke
A12: MK-76 | B12: MK-76 | C12: Påvirker ikke os - men det her krav er et godt eksempel på en Kunde der beskriver en løsning frem for et behov. Hvorfor skal det være browserbaseret?
... A53: Fordeling af krav | B53: I udbudsmaterialet findes der følgende fordeling af krav: - ca. 217 krav (83 %) er klassificeret som Mindstekrav, - ca. 33 krav (13 %) er klassificeret som Krav, - kun ca. 12 krav (4 %) er klassificeret som Evalueringskrav. | C53: Tommelfingerreglen for offentlige udbud er, at kun omkring 10% af et udbuds totale antal krav bør være mindstekrav.

Sheet Q&A
A1: # | B1: Relates to requirement ID | C1: Sender | D1: Question | E1: Sent Date | F1: Answer | G1: Received Date | H1: Customer answer ID | I1: Comment
A2: 1 | B2: Leveringskontrakten: Punkt 16.1 (Forsinkelse) Punkt 16.3 (Bod) Punkt 16.4 (Erstatning) Bilag 1.h Servicemål (SLA-bod) Bilag 5 CSR (CSR-bod) Bilag 6 Trepartsaftale (bod ved mangelfuld rapportering til SKI) | C2: Tieto | D2: Spørgsmål vedrørende kumulation af bod Leveringskontrakten og de tilhørende bilag indeholder flere selvstændige bodsregimer, herunder bod ved forsinkelse og mangler efter Leveringskontraktens pkt. 16.3, bod efter Bilag 1.h Servicemål, CSR-relateret bod efter Bilag 5 og bod efter Bilag 6 Trepartsaftale. Tilbudsgiver kan ikke entydigt fastslå, om samme hændelse eller samme underliggende misligholdelse kan udløse bod efter flere af disse bestemmelser samtidig, eller om de enkelte bodsregimer skal anses som alternative. Ordregiver bedes derfor præcisere, om bod kan kumuleres på tværs af Leveringskontrakten og bilagene for samme hændelse eller samme underliggende misligholdelse. Såfremt bod kan kumuleres, bedes Ordregiver samtidig oplyse, om der gælder et samlet maksimum for den bod, som Leverandøren kan pålægges på tværs af Leveringskontrakten, Bilag 1.h, Bilag 5 og Bilag 6. Hvis der ikke gælder et sådant samlet loft, bedes Ordregiver overveje at indføre dette, således at Leverandørens samlede bodeksponering kan fastlægges entydigt ved tilbudsafgivelsen. | I2: Omformuleret.
A3: 2 | B3: Bilag 1 Kundens opgavebeskrivelse Punkt 2.2 Support og vedligeholdelse Punkt 2.3 Implementering Punkt 3 Eksisterende it-miljø Punkt 4 Tidsplan Bilag 1.c Kundens eksisterende it-landskab Bilag 1.g Samarbejde under Leveringskontrakten Bilag 1.h Servicemål Bilag 1.l Statens IT's driftsmodeller | C3: Tieto | D3: Spørgsmål vendrørende ansvar for forhold hos Statens IT Det fremgår af Bilag 1.l, at ansvaret for driften under Driftsmodel 3 er fordelt mellem Kunden/Leverandøren og Statens IT, herunder således at Statens IT har ansvar for operativsystem, server/storage og netværk, mens Kunden har ansvar for applikation og middleware. Tilbudsgiver bemærker samtidig, at Leverandøren er underlagt servicemål og potentielle bodskrav efter Bilag 1.h. Tilbudsgiver kan ikke entydigt fastslå, hvordan servicemål og misligholdelsesbeføjelser håndteres, hvis manglende tilgængelighed, performance eller anden manglende opfyldelse helt eller delvist skyldes forhold ved de komponenter eller driftsopgaver, som Statens IT er ansvarlig for. Ordregiver bedes derfor bekræfte, at Leverandøren ikke ifalder bod, erstatningsansvar eller øvrige misligholdelsesbeføjelser i det omfang en manglende opfyldelse skyldes forhold, som henhører under Statens IT's ansvarsområde. Ordregiver bedes samtidig præcisere, hvordan årsagen til en sådan hændelse fastlægges, og hvordan servicemålsberegningen håndteres, mens det undersøges, om hændelsen skyldes ESDH-løsningen eller Statens IT's infrastruktur. | I3: Omformuleret.
A4: 4 | B4: Bilag 1.b Krav til standardsoftware Samtlige MK, K og EK Bilag 1.e Krav til IT- og informationssikkerhed Samtlige MK og K Opfordringsskrivelsen Afsnit om evaluering Afsnit om konditionsmæssighed | C4: Tieto | D4: I udbudsmaterialet findes der følgende fordeling af krav: - ca. 217 krav (83 %) er klassificeret som Mindstekrav, - ca. 33 krav (13 %) er klassificeret som Krav, - kun ca. 12 krav (4 %) er klassificeret som Evalueringskrav. Det betyder, at langt hovedparten af kravene er ufravigelige Mindstekrav, som tilbudsgiver skal opfylde, mens kun en meget begrænset del af kravene giver mulighed for, at Ordregiver kan evaluere forskellige løsningsforslag og deres kvalitet. Tommelfingerreglen for offentlige udbud er, at kun omkring 10% af et udbuds totale antal krav bør være mindstekrav. Efter vores opfattelse indebærer en så høj andel af detaljerede Mindstekrav en risiko for, at konkurrencen begrænses unødigt, idet leverandørerne kun i begrænset omfang får mulighed for at konkurrere på forskellige standardfunktionaliteter, arkitekturvalg og løsningsmetoder. Dette gælder særligt, når Mindstekravene omfatter detaljerede krav til funktionalitet, brugergrænseflade og systemarkitektur frem for de bagvedliggende forretningsmæssige behov. Ordregiver bedes derfor oplyse: Hvilke overvejelser ligger til grund for, at ca. 83 % af kravene er udformet som Mindstekrav? Har Ordregiver vurderet, om alle disse krav er nødvendige som ufravigelige Mindstekrav, eller om en del af kravene kunne være udformet som Krav eller Evalueringskrav, således at forskellige standardløsninger kunne konkurrere på deres respektive styrker? Hvordan har Ordregiver sikret, at kravspecifikationen er udformet i overensstemmelse med udbudslovens § 42 om tekniske specifikationer, således at kravene ikke i praksis favoriserer bestemte produkter eller leverandører, men giver alle relevante standardløsninger mulighed for at konkurrere på lige vilkår? Hvordan har Ordregiver vurderet, at den valgte kravstruktur er forenelig med udbudslovens § 2 om ligebehandling og proportionalitet, når langt størstedelen af kravene er gjort til ufravigelige Mindstekrav? Baggrunden for spørgsmålene er, at en kravspecifikation med en meget høj andel af detaljerede Mindstekrav kan medføre, at konkurrencen i praksis begrænses til standardløsninger, som allerede er indrettet efter netop disse krav. Leverandører, der kan opfylde Ordregivers behov gennem andre standardfunktionaliteter eller en anden systemarkitektur, kan dermed få vanskeligere ved at konkurrere, selv om løsningen opfylder de bagvedliggende forretningsmæssige behov. Ordregiver bedes derfor redegøre for, hvilke konkrete vurderinger der er foretaget for at sikre, at kravspecifikationen ikke begrænser konkurrencen mere end nødvendigt, og at de opstillede Mindstekrav er proportionale og objektivt nødvendige for at opfylde Ordregivers behov. | I4: Udgår - er blevet spurgt af konkurrent - kunden fastholder.
A5: 5 | B5: Opfordringsskrivelsen Afsnit 3 Skriftlige spørgsmål Tidsplanen for spørgsmål og svar Tilbudsfrister | C5: Tieto | D5: Ordregiver har anført, at tilbudsgiverne i perioden fra den 10. juli 2026 til den 2. august 2026 ikke kan forvente at modtage svar på indsendte spørgsmål. Udbudsmaterialet er omfattende og indeholder et betydeligt antal detaljerede tekniske, kontraktuelle og sikkerhedsmæssige krav. For at kunne udarbejde et kvalificeret og konkurrencedygtigt tilbud er tilbudsgiverne afhængige af løbende afklaring af spørgsmål til udbudsmaterialet. Ordregiver bedes derfor redegøre for, hvordan det er vurderet, at den lange periode uden mulighed for afklaring giver tilbudsgiverne tilstrækkelige muligheder for at udarbejde et fuldt oplyst og konkurrencedygtigt tilbud på lige vilkår. Har Ordregiver overvejet enten: at besvare spørgsmål løbende i ferieperioden, at forlænge tilbudsfristen tilsvarende, eller at forlænge fristen for indsendelse af spørgsmål, således at tilbudsgiverne reelt har mulighed for at få afklaret væsentlige forhold i udbudsmaterialet inden tilbudsafgivelsen? | I5: Udgår
A6: 6 | B6: Bilag 1 Kundens opgavebeskrivelse Punkt 2.3 Implementering Punkt 4 Tidsplan Bilag 1.g Samarbejde under Leveringskontrakten Kapitel 3 Samarbejdsorganisation i implementeringsfasen Punkt 3.5 Projektledelse | C6: Tieto | D6: Udbudsmaterialet beskriver, at implementeringen skal gennemføres i et tæt samarbejde mellem Ordregiver og Leverandøren, og at begge parter har væsentlige roller i projektets gennemførelse. Ordregiver bedes derfor oplyse, hvem der forventes at varetage projektlederrollen på Ordregivers side under implementeringsfasen. Er det Ordregivers forventning, at projektledelsen varetages af interne medarbejdere, eller forventes projektledelsen helt eller delvist varetaget af en ekstern rådgiver? Såfremt Ordregiver forventer at anvende en ekstern rådgiver, bedes Ordregiver oplyse, om denne vil være den samme rådgiver, som har bistået Ordregiver med udarbejdelsen af udbudsmaterialet og den forudgående anskaffelsesproces. Baggrunden for spørgsmålet er, at projektorganisationen, projektledelsens rolle og graden af kontinuitet mellem udbudsfasen og implementeringsfasen har væsentlig betydning for implementeringsrisikoen, governance, beslutningsprocesser og samarbejdsmodellen. Disse forhold indgår direkte i tilbudsgivernes vurdering af risiko og dermed i prissætningen af implementeringsopgaven. En afklaring vil derfor bidrage til en mere ensartet risikovurdering og prissætning blandt tilbudsgiverne.
